Workbook
Name celpeCEE: '[1]@Referência'!$K$16:$K$18
Name ListaSimNao: '[1]@Referência'!$A$30:$A$31
Name Modalidade: '[1]@Referência'!$J$2:$J$6
Name tipoCELPE: '[1]@Referência'!$N$14:$N$18

Sheet Tabela de Transferência
A1: Campo | B1: Página | C1: Endereço.tex | D1: chave | E1: valor
A2: Inserir Mome do RT | B2: Capa | C2: TCC_Final_CCEE.tex | D2: <<nomeRt>> | E2: =IFERROR(UC_DADOS!B7,0) -> 71 9935-2628
A3: NOME DA UNIDADE CONSUMIDORA DA PMS | B3: Capa | C3: TCC_Final_CCEE.tex | D3: <<nomeUc>> | E3: =IFERROR(UC_DADOS!B1,0) -> MUNICIPIO DE SALVADOR 744 CMEI OLGA BENARIO
A4: Data | B4: Capa | C4: TCC_Final_CCEE.tex | D4: <<data>> | E4: =IFERROR(UC_DADOS!B8,0) -> 46086
A5: Inserir Mome do RT | B5: Contra Capa | C5: TCC_Final_CCEE.tex | D5: <<nomeRt>> | E5: =IFERROR(E2,0) -> 71 9935-2628
A6: NOME DA UNIDADE CONSUMIDORA DA PMS | B6: Contra Capa | C6: TCC_Final_CCEE.tex | D6: <<nomeUc>> | E6: =IFERROR(E3,0) -> MUNICIPIO DE SALVADOR 744 CMEI OLGA BENARIO
A7: Nome da UC | B7: Contra Capa | C7: TCC_Final_CCEE.tex | D7: <<nomeUc>> | E7: =IFERROR(E6,0) -> MUNICIPIO DE SALVADOR 744 CMEI OLGA BENARIO
A8: Data | B8: Contra Capa | C8: TCC_Final_CCEE.tex | D8: <<data>> | E8: =IFERROR(E4,0) -> 46086
A9: Nome da Unidade | B9: 6 | C9: capitulo1.tex | D9: <<nomeUc>> | E9: =IFERROR(E3,0) -> MUNICIPIO DE SALVADOR 744 CMEI OLGA BENARIO
A10: Código da UC | B10: 6 | C10: capitulo1.tex | D10: <<codigoUc>> | E10: =IFERROR(UC_DADOS!B2,0) -> 7041435180
A11: Tipo de Atividade | B11: 6 | C11: capitulo1.tex | D11: <<tipoAtividade>> | E11: =IFERROR(UC_DADOS!B3,0) -> Escola
A12: Endereço Completo | B12: 6 | C12: capitulo1.tex | D12: <<endereco>> | E12: =IFERROR(UC_DADOS!B4,0) -> Rua Fernando São Paulo, Dóron
A13: Responsável / Cargo | B13: 6 | C13: capitulo1.tex | D13: <<responsavel>> | E13: =IFERROR(UC_DADOS!B6,0) -> Silvia
A14: Telefone para Contato | B14: 6 | C14: capitulo1.tex | D14: <<telefone>> | E14: =IFERROR(UC_DADOS!B7,0) -> 71 9935-2628
A15: E-mail Institucional | B15: 6 | C15: capitulo1.tex | D15: <<email>> | E15: =IFERROR(UC_DADOS!B9,0) -> educacao@prefs.com.br
A16: Adcionar Localidade | B16: 8 | C16: capitulo3.tex | D16: <<localidade>> | E16: =IFERROR(UC_DADOS!B5,0) -> Dóron, Salvador-BA
A17: Iluminação / Medida Proposta | B17: 11 | C17: capitulo4.tex | D17: <<propIluminacao>> | E17: =IFERROR(TABELAS_RESUMO!B12,0) -> Substituição por LED e sensores
A18: Climatização / Medida Proposta | B18: 11 | C18: capitulo4.tex | D18: <<propClimatizacao>> | E18: =IFERROR(TABELAS_RESUMO!B13,0) -> Troca de aparelhos de ar-condicionado e automação
A19: Motores / Medida Proposta | B19: 11 | C19: capitulo4.tex | D19: <<propMotores>> | E19: =IFERROR(TABELAS_RESUMO!B14,0) -> Substituição por motores de alto rendimento
A20: Refrigeração / Medida Proposta | B20: 11 | C20: capitulo4.tex | D20: <<propRefrigeracao>> | E20: =IFERROR(TABELAS_RESUMO!B15,0) -> Troca de refrigeradores comerciais ineficientes
A21: Fotovoltaico / Medida Proposta | B21: 11 | C21: capitulo4.tex | D21: <<propFotovoltaico>> | E21: =IFERROR(TABELAS_RESUMO!B16,0) -> Sistema conectado à rede (GD)
A22: Iluminação / Economia (MWh/ano) | B22: 11 | C22: capitulo4.tex | D22: <<iluEconomia>> | E22: =IFERROR(TABELAS_RESUMO!C12,0) -> 0
A23: Climatização / Economia (MWh/ano) | B23: 11 | C23: capitulo4.tex | D23: <<cliEconomia>> | E23: =IFERROR(TABELAS_RESUMO!C13,0) -> 0
A24: Motores / Economia (MWh/ano) | B24: 11 | C24: capitulo4.tex | D24: <<motEconomia>> | E24: =IFERROR(TABELAS_RESUMO!C14,0) -> 0
A25: Refrigeração / Economia (MWh/ano) | B25: 11 | C25: capitulo4.tex | D25: <<refEconomia>> | E25: =IFERROR(TABELAS_RESUMO!C15,0) -> 0
A26: Fotovoltaico / Economia (MWh/ano) | B26: 11 | C26: capitulo4.tex | D26: <<fotEconomia>> | E26: =IFERROR(TABELAS_RESUMO!C16,0) -> 0
A27: Total / Economia (MWh/ano) | B27: 11 | C27: capitulo4.tex | D27: <<totEconomia>> | E27: =IFERROR(TABELAS_RESUMO!C17,0) -> 0
A28: Iluminação / Invest. Total (R$) | B28: 11 | C28: capitulo4.tex | D28: <<iluInvestimento>> | E28: =IFERROR(TABELAS_RESUMO!D12,0) -> 0
A29: Climatização / Invest. Total (R$) | B29: 11 | C29: capitulo4.tex | D29: <<cliInvestimento>> | E29: =IFERROR(TABELAS_RESUMO!D13,0) -> 0
A30: Motores / Invest. Total (R$) | B30: 11 | C30: capitulo4.tex | D30: <<motInvestimento>> | E30: =IFERROR(TABELAS_RESUMO!D14,0) -> 0
A31: Refrigeração / Invest. Total (R$) | B31: 11 | C31: capitulo4.tex | D31: <<refInvestimento>> | E31: =IFERROR(TABELAS_RESUMO!D15,0) -> 0
A32: Fotovoltaico / Invest. Total (R$) | B32: 11 | C32: capitulo4.tex | D32: <<fotInvestimento>> | E32: =IFERROR(TABELAS_RESUMO!D16,0) -> 0
A33: Total / Invest. Total (R$) | B33: 11 | C33: capitulo4.tex | D33: <<totInvestimento>> | E33: =IFERROR(TABELAS_RESUMO!D17,0) -> 0
A34: Iluminação / PB | B34: 11 | C34: capitulo4.tex | D34: <<iluPayBack>> | E34: =IFERROR(TABELAS_RESUMO!E12,0) -> 0
A35: Climatização / PB | B35: 11 | C35: capitulo4.tex | D35: <<cliPayBack>> | E35: =IFERROR(TABELAS_RESUMO!E13,0) -> 0
A36: Motores / PB | B36: 11 | C36: capitulo4.tex | D36: <<motPayBack>> | E36: =IFERROR(TABELAS_RESUMO!E14,0) -> 0
A37: Refrigeração / PB | B37: 11 | C37: capitulo4.tex | D37: <<refPayBack>> | E37: =IFERROR(TABELAS_RESUMO!E15,0) -> 0
A38: Fotovoltaico / PB | B38: 11 | C38: capitulo4.tex | D38: <<fotPayBack>> | E38: =IFERROR(TABELAS_RESUMO!E16,0) -> 0
A39: Total / PB | B39: 11 | C39: capitulo4.tex | D39: <<totPayBack>> | E39: =IFERROR(TABELAS_RESUMO!E17,0) -> 0
A40: Nome da Unidade | B40: 12 | C40: capitulo5.tex | D40: <<nomeUc>> | E40: =IFERROR(E3,0) -> MUNICIPIO DE SALVADOR 744 CMEI OLGA BENARIO
...

Sheet FATURAS
A1: id_fatura | B1: status_pagamento | C1: status_leitura | D1: nome_empresa_cliente | E1: valor_total_em_reais | F1: nome_uc | G1: tipo_uc | H1: nome_grupo_uc | I1: tipo_instalacao | J1: nome_distribuidora_energia | K1: data_emissao | L1: data_vencimento | M1: periodo_referencia | N1: proxima_leitura_fatura | O1: leitura_atual_fatura | P1: ultima_leitura_fatura | Q1: numero_dias | R1: consumo_minimo | S1: id_ultima_fatura | T1: periodo_referencia_ultima_fatura | U1: demanda_contratada | V1: demanda_contratada_ponta | W1: demanda_contratada_fora_ponta | X1: nome_classe | Y1: descricao_classe | Z1: tipo_fornecimento | AA1: codigo_cliente | AB1: codigo_instalacao | AC1: consumo_total | AD1: consumo_total_com_perda_transformacao | AE1: consumo_compensado_total | AF1: consumo_faturado_total | AG1: energia_total_injetada | AH1: consumo_ponta | AI1: consumo_ponta_com_perda_transformacao | AJ1: consumo_fora_ponta | AK1: consumo_fora_ponta_com_perda_transformacao | AL1: consumo_intermediario | AM1: consumo_intermediario_com_perda_transformacao | AN1: consumo_compensado_ponta | AO1: consumo_compensado_fora_ponta | AP1: consumo_compensado_intermediário | AQ1: consumo_faturado_ponta | AR1: consumo_faturado_fora_ponta | AS1: consumo_faturado_intermediario | AT1: demanda_maxima | AU1: demanda_maxima_ponta | AV1: demanda_maxima_fora_ponta | AW1: demanda_de_ultrapassagem | AX1: demanda_de_ultrapassagem_ponta | AY1: demanda_de_ultrapassagem_fora_ponta | AZ1: demanda_faturada | BA1: demanda_faturada_ponta | BB1: demanda_faturada_fora_ponta | BC1: consumo_reativo_total | BD1: consumo_reativo_ponta | BE1: consumo_reativo_fora_ponta | BF1: consumo_reativo_excedente_total | BG1: consumo_reativo_excedente_ponta | BH1: consumo_reativo_excedente_fora_ponta | BI1: demanda_reativa_excedente | BJ1: demanda_reativa_excedente_ponta | BK1: demanda_reativa_excedente_fora_ponta | BL1: fator_carga_ponta | BM1: fator_carga_fora_ponta | BN1: percentual_perda_transformacao | BO1: creditos_acumulados_anterior | BP1: creditos_acumulados | BQ1: movimentacao_creditos_mes | BR1: tarifa_consumo_ponta | BS1: tarifa_consumo_fora_ponta | BT1: tarifa_consumo_intermediario | BU1: tarifa_consumo_convencional | BV1: tarifa_demanda_maxima | BW1: tarifa_demanda_de_ultrapassagem | BX1: tarifa_demanda_de_ultrapassagem_ponta | BY1: tarifa_demanda_de_ultrapassagem_fora_ponta | BZ1: tarifa_demanda_maxima_ponta | CA1: tarifa_demanda_maxima_fora_ponta | CB1: tarifa_consumo_reativo_excedente | CC1: tarifa_demanda_reativa_excedente | CD1: tarifa_calculada_demanda_ultrapassada | CE1: tarifa_calculada_demanda_de_ultrapassagem_ponta | CF1: tarifa_calculada_demanda_de_ultrapassagem_fora_ponta | CG1: tarifa_efetiva_de_consumo | CH1: valor_total_icms | CI1: base_calculo_icms | CJ1: aliquota_icms | CK1: valor_total_pis | CL1: base_calculo_pis | CM1: aliquota_pis | CN1: valor_total_cofins | CO1: base_calculo_cofins | CP1: aliquota_cofins | CQ1: numero_nota_fiscal | CR1: url_nota_fiscal | CS1: chave_acesso_nota_fiscal | CT1: arquivo_anexo | CU1: potencial_de_economia_mensal | CV1: potencial_de_economia_anual | CW1: potencial_de_economia_12_meses
A2: efd0aaeb-5a6f-4882-94c5-f68fdc24c33f | B2: Pendente | C2: Sucesso | D2: Prefeitura de Salvador | E2: 4707.45 | F2: MUNICIPIO DE SALVADOR 744 CMEI OLGA BENARIO | G2: Consumidora | H2: - | I2: - | J2: Neoenergia Coelba - Bahia | K2: 46140 | L2: 46170 | M2: 46082 | N2: 46142 | O2: 46112 | P2: 46081 | Q2: 31 | R2: 0 | S2: - | T2: - | U2: 80 | V2: - | W2: - | X2: Alta Tensão - Verde | Y2: A4 Horo-sazonal Verde PODER PUBLICO MUNICIPAL | Z2: Trifásico | AA2: 7041435180 | AB2: 11039337 | AC2: 3282.5 | AD2: 3364.57 | AE2: 0 | AF2: 3364.56 | AG2: - | AH2: 80.9 | AI2: 82.93 | AJ2: 3201.6 | AK2: 3281.64 | AL2: - | AM2: - | AN2: 0 | AO2: 0 | AP2: - | AQ2: 82.92 | AR2: 3281.64 | AS2: - | AT2: 34.08 | AU2: 2.3 | AV2: 34.08 | AW2: 0 | AX2: - | AY2: - | AZ2: 80 | BA2: - | BB2: - | BC2: 0 | BD2: 0 | BE2: 0 | BF2: 82.41 | BG2: 0 | BH2: 82.41 | BI2: 0 | BJ2: - | BK2: - | BL2: 0.53 | BM2: 0.14 | BN2: 2.5 | BO2: - | BP2: - | BQ2: - | BR2: 3.3227706 | BS2: 0.38957284 | BT2: - | BU2: - | BV2: 41.333904 | BW2: - | BX2: - | BY2: - | BZ2: - | CA2: - | CB2: 0.29679905 | CC2: 41.333904 | CD2: 82.667809 | CE2: - | CF2: - | CG2: 0.46186399 | CH2: 0 | CI2: 0 | CJ2: 0.205 | CK2: 57.15 | CL2: 4885.11 | CM2: 0.0117 | CN2: 264.77 | CO2: 4885.11 | CP2: 0.0542 | CQ2: 958129091 | CR2: https://dfe-portal.svrs.rs.gov.br/Nf3e/consulta | CS2: 2926 0415 1396 2900 0194 6600 0958 1290 9110 6404 5386 | CT2: collective-invoice-deea8a88-456f-4091-a6e6-d5784cc86269-35.pdf | CU2: 0 | CV2: 0 | CW2: 0
A3: 837ac22a-067c-4438-a24a-7b6f34bf5707 | B3: Em atraso | C3: Sucesso | D3: Prefeitura de Salvador | E3: 3697.51 | F3: MUNICIPIO DE SALVADOR 744 CMEI OLGA BENARIO | G3: Consumidora | H3: - | I3: - | J3: Neoenergia Coelba - Bahia | K3: 46108 | L3: 46140 | M3: 46054 | N3: 46112 | O3: 46081 | P3: 46053 | Q3: 28 | R3: 0 | S3: - | T3: - | U3: 80 | V3: - | W3: - | X3: Alta Tensão - Verde | Y3: A4 Horo-sazonal Verde PODER PUBLICO MUNICIPAL | Z3: Trifásico | AA3: 7041435180 | AB3: 11039337 | AC3: 1022.17 | AD3: 1047.73 | AE3: 0 | AF3: 1047.72 | AG3: - | AH3: 48.97 | AI3: 50.2 | AJ3: 973.2 | AK3: 997.53 | AL3: - | AM3: - | AN3: 0 | AO3: 0 | AP3: - | AQ3: 50.19 | AR3: 997.53 | AS3: - | AT3: 11.71 | AU3: 1.2 | AV3: 11.71 | AW3: 0 | AX3: - | AY3: - | AZ3: 80 | BA3: - | BB3: - | BC3: 0 | BD3: 0 | BE3: 0 | BF3: 109.47 | BG3: 0 | BH3: 109.47 | BI3: 0 | BJ3: - | BK3: - | BL3: 0.76 | BM3: 0.13 | BN3: 2.5 | BO3: - | BP3: - | BQ3: - | BR3: 3.2949045 | BS3: 0.38630572 | BT3: - | BU3: - | BV3: 40.987261 | BW3: - | BX3: - | BY3: - | BZ3: - | CA3: - | CB3: 0.29430997 | CC3: 40.987261 | CD3: 81.974522 | CE3: - | CF3: - | CG3: 0.52565053 | CH3: 0 | CI3: 0 | CJ3: 0.205 | CK3: 39.77 | CL3: 3861.9 | CM3: 0.0103 | CN3: 184.21 | CO3: 3861.9 | CP3: 0.0477 | CQ3: 950416389 | CR3: https://dfe-portal.svrs.rs.gov.br/Nf3e/consulta | CS3: 2926 0315 1396 2900 0194 6600 0950 4163 8910 8451 8124 | CT3: collective-invoice-12601260-bf07-4e7f-b254-7e6122f0dd9f-25.pdf | CU3: 1917.61 | CV3: 3808.37 | CW3: 3808.37
A4: 8e6595e3-396c-4675-8e1b-22789a865feb | B4: Em atraso | C4: Sucesso | D4: Prefeitura de Salvador | E4: 4517.9 | F4: MUNICIPIO DE SALVADOR 744 CMEI OLGA BENARIO | G4: Consumidora | H4: - | I4: - | J4: Neoenergia Coelba - Bahia | K4: 46079 | L4: 46111 | M4: 46023 | N4: 46081 | O4: 46053 | P4: 46022 | Q4: 31 | R4: 0 | S4: - | T4: - | U4: 80 | V4: - | W4: - | X4: Alta Tensão - Verde | Y4: A4 Horo-sazonal Verde PODER PUBLICO PUBLICO | Z4: Trifásico | AA4: 7041435180 | AB4: 11039337 | AC4: 2804.63 | AD4: 2874.74 | AE4: 0 | AF4: 2874.75 | AG4: - | AH4: 84.23 | AI4: 86.33 | AJ4: 2720.4 | AK4: 2788.41 | AL4: - | AM4: - | AN4: 0 | AO4: 0 | AP4: - | AQ4: 86.34 | AR4: 2788.41 | AS4: - | AT4: 33.98 | AU4: 2.69 | AV4: 33.98 | AW4: 0 | AX4: - | AY4: - | AZ4: 80 | BA4: - | BB4: - | BC4: 0 | BD4: 0 | BE4: 0 | BF4: 104.55 | BG4: 0 | BH4: 104.55 | BI4: 0 | BJ4: - | BK4: - | BL4: 0.5 | BM4: 0.12 | BN4: 2.5 | BO4: - | BP4: - | BQ4: - | BR4: 3.3100138 | BS4: 0.3880772 | BT4: - | BU4: - | BV4: 41.175216 | BW4: - | BX4: - | BY4: - | BZ4: - | CA4: - | CB4: 0.29565959 | CC4: 41.175216 | CD4: 82.350432 | CE4: - | CF4: - | CG4: 0.47583021 | CH4: 0 | CI4: 0 | CJ4: 0.205 | CK4: 52.09 | CL4: 4692.8 | CM4: 0.0111 | CN4: 240.27 | CO4: 4692.8 | CP4: 0.0512 | CQ4: 942948518 | CR4: https://dfe-portal.svrs.rs.gov.br/Nf3e/consulta | CS4: 2926 0215 1396 2900 0194 6600 0942 9485 1810 0630 5937 | CT4: collective-invoice-daced704-b68a-4dd6-8470-e22789ce44ea-15.pdf | CU4: 1842.59 | CV4: 1842.59 | CW4: 1842.59
A5: 2f4256a8-45ef-440c-bfb5-5d569ca2fd29 | B5: Em atraso | C5: Sucesso | D5: Prefeitura de Salvador | E5: 4873.8 | F5: MUNICIPIO DE SALVADOR 744 CMEI OLGA BENARIO | G5: Consumidora | H5: - | I5: - | J5: Neoenergia Coelba - Bahia | K5: 46051 | L5: 46083 | M5: 45992 | N5: 46053 | O5: 46022 | P5: 45991 | Q5: 31 | R5: 0 | S5: - | T5: - | U5: 80 | V5: - | W5: - | X5: Alta Tensão - Verde | Y5: A4 Horo-sazonal Verde PODER PUBLICO MUNICIPAL | Z5: Trifásico | AA5: 7041435180 | AB5: 11039337 | AC5: 3476.05 | AD5: 3562.95 | AE5: 0 | AF5: 3562.95 | AG5: - | AH5: 80.05 | AI5: 82.05 | AJ5: 3396 | AK5: 3480.9 | AL5: - | AM5: - | AN5: 0 | AO5: 0 | AP5: - | AQ5: 82.05 | AR5: 3480.9 | AS5: - | AT5: 33.22 | AU5: 2.3 | AV5: 33.22 | AW5: 0 | AX5: - | AY5: - | AZ5: 80 | BA5: - | BB5: - | BC5: 0 | BD5: 0 | BE5: 0 | BF5: 138 | BG5: 0 | BH5: 138 | BI5: 0 | BJ5: - | BK5: - | BL5: 0.53 | BM5: 0.15 | BN5: 2.5 | BO5: - | BP5: - | BQ5: - | BR5: 3.3458159 | BS5: 0.41010392 | BT5: - | BU5: - | BV5: 41.369335 | BW5: - | BX5: - | BY5: - | BZ5: - | CA5: - | CB5: 0.29705346 | CC5: 41.369335 | CD5: 82.738669 | CE5: - | CF5: - | CG5: 0.47771047 | CH5: 0 | CI5: 0 | CJ5: 0.205 | CK5: 60.13 | CL5: 5053.59 | CM5: 0.0119 | CN5: 276.93 | CO5: 5053.59 | CP5: 0.0548 | CQ5: 935272040 | CR5: https://dfe-portal.svrs.rs.gov.br/Nf3e/consulta | CS5: 2926 0115 1396 2900 0194 6600 0935 2720 4010 3357 0648 | CT5: collective-invoice-7b320f96-ced8-4aaa-9885-ebb0fb4b5884-25.pdf | CU5: 1850.82 | CV5: 6895.52 | CW5: 6895.52
A6: d322cff7-3df0-46fd-ba6d-c3350bb8d5ab | B6: Em atraso | C6: Sucesso | D6: Prefeitura de Salvador | E6: 4877.45 | F6: MUNICIPIO DE SALVADOR 744 CMEI OLGA BENARIO | G6: Consumidora | H6: - | I6: - | J6: Neoenergia Coelba - Bahia | K6: 46020 | L6: 46050 | M6: 45962 | N6: 46022 | O6: 45991 | P6: 45961 | Q6: 30 | R6: 0 | S6: - | T6: - | U6: 80 | V6: - | W6: - | X6: Alta Tensão - Verde | Y6: A4 Horo-sazonal Verde PODER PUBLICO MUNICIPAL | Z6: Trifásico | AA6: 7041435180 | AB6: 11039337 | AC6: 3167.94 | AD6: 3247.14 | AE6: 0 | AF6: 3247.14 | AG6: - | AH6: 73.14 | AI6: 74.97 | AJ6: 3094.8 | AK6: 3172.17 | AL6: - | AM6: - | AN6: 0 | AO6: 0 | AP6: - | AQ6: 74.97 | AR6: 3172.17 | AS6: - | AT6: 34.37 | AU6: 2.11 | AV6: 34.37 | AW6: 0 | AX6: - | AY6: - | AZ6: 80 | BA6: - | BB6: - | BC6: 0 | BD6: 0 | BE6: 0 | BF6: 186.96 | BG6: 0 | BH6: 186.96 | BI6: 0 | BJ6: - | BK6: - | BL6: 0.61 | BM6: 0.14 | BN6: 2.5 | BO6: - | BP6: - | BQ6: - | BR6: 3.4084984 | BS6: 0.44227562 | BT6: - | BU6: - | BV6: 41.799285 | BW6: - | BX6: - | BY6: - | BZ6: - | CA6: - | CB6: 0.30014073 | CC6: 41.799285 | CD6: 83.598571 | CE6: - | CF6: - | CG6: 0.51075846 | CH6: 0 | CI6: 0 | CJ6: 0.205 | CK6: 68.79 | CL6: 5058.54 | CM6: 0.0136 | CN6: 317.17 | CO6: 5058.54 | CP6: 0.0627 | CQ6: 927319924 | CR6: https://dfe-portal.svrs.rs.gov.br/Nf3e/consulta | CS6: 2925 1215 1396 2900 0194 6600 0927 3199 2410 4836 4427 | CT6: collective-invoice-04e96beb-34a5-455b-8925-28e515dab6e7-16.pdf | CU6: 2010.35 | CV6: 5044.7 | CW6: 5044.7
A7: 92da71dc-128d-4227-9458-1c77a714807c | B7: Em atraso | C7: Sucesso | D7: Prefeitura de Salvador | E7: 4412.8 | F7: MUNICIPIO DE SALVADOR 744 CMEI OLGA BENARIO | G7: Consumidora | H7: - | I7: - | J7: Neoenergia Coelba - Bahia | K7: 45988 | L7: 46020 | M7: 45931 | N7: 45991 | O7: 45961 | P7: 45930 | Q7: 31 | R7: 0 | S7: - | T7: - | U7: 80 | V7: - | W7: - | X7: Alta Tensão - Verde | Y7: A4 Horo-sazonal Verde PODER PUBLICO MUNICIPAL | Z7: Trifásico | AA7: 7041435180 | AB7: 11039337 | AC7: 2151.49 | AD7: 2205.28 | AE7: 0 | AF7: 2205.28 | AG7: - | AH7: 89.89 | AI7: 92.14 | AJ7: 2061.6 | AK7: 2113.14 | AL7: - | AM7: - | AN7: 0 | AO7: 0 | AP7: - | AQ7: 92.14 | AR7: 2113.14 | AS7: - | AT7: 29.23 | AU7: 2.54 | AV7: 29.23 | AW7: 0 | AX7: - | AY7: - | AZ7: 80 | BA7: - | BB7: - | BC7: 469.39 | BD7: 42.19 | BE7: 427.2 | BF7: 96.8 | BG7: 9.47 | BH7: 87.33 | BI7: 0 | BJ7: - | BK7: - | BL7: 0.51 | BM7: 0.1 | BN7: 2.5 | BO7: - | BP7: - | BQ7: - | BR7: 3.3832259 | BS7: 0.43899634 | BT7: - | BU7: - | BV7: 41.489362 | BW7: - | BX7: - | BY7: - | BZ7: - | CA7: - | CB7: 0.29791532 | CC7: 41.489362 | CD7: 82.978723 | CE7: - | CF7: - | CG7: 0.56200727 | CH7: 0 | CI7: 0 | CJ7: 0.205 | CK7: 56.88 | CL7: 4587.34 | CM7: 0.0124 | CN7: 261.47 | CO7: 4587.34 | CP7: 0.057 | CQ7: 919897917 | CR7: https://dfe-portal.svrs.rs.gov.br/Nf3e/consulta | CS7: 2925 1115 1396 2900 0194 6600 0919 8979 1710 7891 5848 | CT7: collective-invoice-f044ebe1-ba65-449c-a53f-a4be3e0b6f2d-19.pdf | CU7: 2167.54 | CV7: 4260.78 | CW7: 4260.78
A8: 27c161b1-fce1-41c6-98a7-d1c850a87e70 | B8: Em atraso | C8: Sucesso | D8: Prefeitura de Salvador | E8: 4004.54 | F8: MUNICIPIO DE SALVADOR 744 CMEI OLGA BENARIO | G8: Consumidora | H8: - | I8: - | J8: Neoenergia Coelba - Bahia | K8: 45897 | L8: 45929 | M8: 45839 | N8: 45900 | O8: 45869 | P8: 45838 | Q8: 31 | R8: 0 | S8: - | T8: - | U8: 80 | V8: - | W8: - | X8: Alta Tensão - Verde | Y8: A4 Horo-sazonal Verde PODER PUBLICO MUNICIPAL | Z8: Trifásico | AA8: 7041435180 | AB8: 11039337 | AC8: 1408.27 | AD8: 1443.48 | AE8: 0 | AF8: 1443.48 | AG8: - | AH8: 73.87 | AI8: 75.72 | AJ8: 1334.4 | AK8: 1367.76 | AL8: - | AM8: - | AN8: 0 | AO8: 0 | AP8: - | AQ8: 75.72 | AR8: 1367.76 | AS8: - | AT8: 25.97 | AU8: 1.58 | AV8: 25.97 | AW8: 0 | AX8: - | AY8: - | AZ8: 80 | BA8: - | BB8: - | BC8: 731.51 | BD8: 67.91 | BE8: 663.6 | BF8: 89.54 | BG8: 18.2 | BH8: 71.34 | BI8: 0 | BJ8: - | BK8: - | BL8: 0.68 | BM8: 0.08 | BN8: 2.5 | BO8: - | BP8: - | BQ8: - | BR8: 3.3597588 | BS8: 0.43595133 | BT8: - | BU8: - | BV8: 41.201579 | BW8: - | BX8: - | BY8: - | BZ8: - | CA8: - | CB8: 0.29584889 | CC8: 41.201579 | CD8: 82.403159 | CE8: - | CF8: - | CG8: 0.58931799 | CH8: 0 | CI8: 0 | CJ8: 0.205 | CK8: 47.15 | CL8: 4173.26 | CM8: 0.0113 | CN8: 215.34 | CO8: 4173.26 | CP8: 0.0516 | CQ8: 897725540 | CR8: https://dfe-portal.svrs.rs.gov.br/Nf3e/consulta | CS8: 2925 0815 1396 2900 0194 6600 0897 7255 4010 5396 8812 | CT8: collective-invoice-b190c713-d90a-47e1-a98e-3287700ea656-15.pdf | CU8: 2237.68 | CV8: 0 | CW8: 0
A9: d7800376-f027-41fe-a21e-e0f0d067ca41 | B9: Em atraso | C9: Sucesso | D9: Prefeitura de Salvador | E9: 1726.23 | F9: MUNICIPIO DE SALVADOR 744 CMEI OLGA BENARIO | G9: Consumidora | H9: - | I9: - | J9: Neoenergia Coelba - Bahia | K9: 45834 | L9: 45866 | M9: 45778 | N9: 45838 | O9: 45808 | P9: 45777 | Q9: 31 | R9: 0 | S9: - | T9: - | U9: 80 | V9: - | W9: - | X9: Alta Tensão - Verde | Y9: A4 Horo-sazonal Verde PODER PUBLICO MUNICIPAL | Z9: Trifásico | AA9: 7041435180 | AB9: 11039337 | AC9: 972.29 | AD9: 996.6 | AE9: 0 | AF9: 996.6 | AG9: - | AH9: 59.09 | AI9: 60.57 | AJ9: 913.2 | AK9: 936.03 | AL9: - | AM9: - | AN9: 0 | AO9: 0 | AP9: - | AQ9: 60.57 | AR9: 936.03 | AS9: - | AT9: 14.45 | AU9: 2.21 | AV9: 14.45 | AW9: 0 | AX9: - | AY9: - | AZ9: 30 | BA9: - | BB9: - | BC9: 708.1 | BD9: 63.7 | BE9: 644.4 | BF9: 0 | BG9: 0 | BH9: 0 | BI9: 0 | BJ9: - | BK9: - | BL9: 0.42 | BM9: 0.09 | BN9: 2.5 | BO9: - | BP9: - | BQ9: - | BR9: 3.27975 | BS9: 0.40200608 | BT9: - | BU9: - | BV9: 40.552463 | BW9: - | BX9: - | BY9: - | BZ9: - | CA9: - | CB9: 0.2911879 | CC9: 40.552463 | CD9: 81.104926 | CE9: - | CF9: - | CG9: 0.57689823 | CH9: 0 | CI9: 0 | CJ9: 0.205 | CK9: 15.4 | CL9: 1791.5 | CM9: 0.0086 | CN9: 70.4 | CO9: 1791.5 | CP9: 0.0393 | CQ9: 882088156 | CR9: https://dfe-portal.svrs.rs.gov.br/Nf3e/consulta | CS9: 2925 0615 1396 2900 0194 5610 | CT9: collective-invoice-ca7fdeb6-dc41-433e-ba48-909609345d55-22.pdf | CU9: 587.45 | CV9: 0 | CW9: 0

Sheet UC_DADOS
A1: Nome da Unidade | B1: =_xlfn.XLOOKUP(MAX(FATURAS!M:M), FATURAS!M:M, FATURAS!F:F,,-1) -> MUNICIPIO DE SALVADOR 744 CMEI OLGA BENARIO
A2: Código da UC | B2: =_xlfn.XLOOKUP(MAX(FATURAS!M:M), FATURAS!M:M, FATURAS!AA:AA,,-1) -> 7041435180
A3: Tipo de Atividade | B3: Escola
A4: Endereço Completo | B4: Rua Fernando São Paulo, Dóron
A5: Localidade | B5: Dóron, Salvador-BA
A6: Responsável / Cargo | B6: Silvia
A7: Telefone para Contato | B7: 71 9935-2628
A8: Data | B8: 46086
A9: E-mail institucional | B9: educacao@prefs.com.br
A12: Alunos | B12: 275
A13: Consumo médio mensal (kWh/mês) | B13: =AVERAGE(FATURAS!AF:AF) -> 2342.81
A14: Consumo específico estimado | B14: =(B13/B12) -> 8.5193091
A18: Modalidade tarifária | B18: =_xlfn.XLOOKUP(MAX(FATURAS!M:M), FATURAS!M:M, FATURAS!X:X,,-1) -> Alta Tensão - Verde
A19: Demanda contratada | B19: =_xlfn.XLOOKUP(MAX(FATURAS!M:M), FATURAS!M:M, FATURAS!U:U,,-1) -> 80
A20: Número da instalação na distribuidora | B20: =_xlfn.XLOOKUP(MAX(FATURAS!M:M),FATURAS!M:M,FATURAS!AB:AB) -> 11039337
A21: Código da unidade consumidora | B21: =B2 -> 7041435180
A22: Classe de consumo | B22: =_xlfn.XLOOKUP(MAX(FATURAS!M:M), FATURAS!M:M, FATURAS!Y:Y,,-1) -> A4 Horo-sazonal Verde PODER PUBLICO MUNICIPAL
A28: Resnposável Técnico | B28: Luiz Carlos Alves Lima
A29: Grupo | B29: =IF(LEFT(B22,1)="A","Grupo A",IF(LEFT(B22,1)="B","Grupo B","")) -> Grupo A
A32: Preço da Energia do Ultimo Mês | B32: =SUMIF(FATURAS!M:M,MAX(FATURAS!M:M),FATURAS!E:E) -> 4707.45
A33: Distribuidora de Energia | B33: =FATURAS!J2 -> Neoenergia Coelba - Bahia
A34: Maior Consumo Registrado (kWh) | B34: =MAX(G37:G48) -> 3562.95
A35: Mês/Ano do Maior Consumo | B35: =INDEX(D37:D48,MATCH(MAX(G37:G48),G37:G48,0)) -> dez/25
A36: Mês/Ano do Menor Consumo | B36: =INDEX(D37:D48,MATCH(MIN(G37:G48),G37:G48,0)) -> Sem Histórico Disponível | D36: Mês / Ano | E36: Consumo Ponta (kWh) | F36: Consumo Fora Ponta (kWh) | G36: Consumo Total (kW) | H36: Demanda Ponta (kW) | I36: Demanda Fora Ponta (kW)
A37: Custo anual de energia elétrica (R$) | B37: =SUMIFS(FATURAS!E:E,FATURAS!M:M,">="&DATE(YEAR(TODAY()),1,1),FATURAS!M:M,"<="&DATE(YEAR(TODAY()),12,31)) -> 12922.86 | D37: =IFERROR(TEXT(SMALL(_xlfn.UNIQUE(FATURAS!M:M),1),"MMM/AA"),"") -> mai/25 | E37: =SUMIFS(FATURAS!AQ:AQ, FATURAS!M:M, SMALL(_xlfn.UNIQUE(FATURAS!M:M),1)) -> 60.57 | F37: =SUMIFS(FATURAS!AR:AR, FATURAS!M:M, SMALL(_xlfn.UNIQUE(FATURAS!M:M),1)) -> 936.03 | G37: =SUM(E37+F37) -> 996.6 | H37: {=SUMPRODUCT( (FATURAS!M2:M5000=SMALL(_xlfn.UNIQUE(FATURAS!M2:M5000),1))* FATURAS!AU2:AU5000* IF(ISNUMBER(FATURAS!BN2:BN5000),1+(FATURAS!BN2:BN5000/100),1))} -> 2.26525 | I37: {=SUMPRODUCT((FATURAS!M2:M5000=SMALL(_xlfn.UNIQUE(FATURAS!M2:M5000),1))*FATURAS!AV2:AV5000*IF(ISNUMBER(FATURAS!BN2:BN5000),1+(FATURAS!BN2:BN5000/100),1))} -> 14.81125
A38: Fator de carga médio estimado | B38: {=IFERROR(SUMPRODUCT(IFERROR(FATURAS!AD2:AD13/(FATURAS!AV2:AV13*FATURAS!Q2:Q13*24),0))/SUMPRODUCT((FATURAS!AV2:AV13<>0)*(FATURAS!Q2:Q13<>0)),0)} -> 0.11546735 | D38: =IFERROR(TEXT(SMALL(_xlfn.UNIQUE(FATURAS!M:M),2),"MMM/AA"),"") -> jul/25 | E38: =SUMIFS(FATURAS!AQ:AQ, FATURAS!M:M, SMALL(_xlfn.UNIQUE(FATURAS!M:M),2)) -> 75.72 | F38: =SUMIFS(FATURAS!AR:AR, FATURAS!M:M, SMALL(_xlfn.UNIQUE(FATURAS!M:M),2)) -> 1367.76 | G38: =SUM(E38+F38) -> 1443.48 | H38: {=SUMPRODUCT( (FATURAS!M2:M5000=SMALL(_xlfn.UNIQUE(FATURAS!M2:M5000),2))* FATURAS!AU2:AU5000* IF(ISNUMBER(FATURAS!BN2:BN5000),1+(FATURAS!BN2:BN5000/100),1))} -> 1.6195 | I38: {=SUMPRODUCT((FATURAS!M2:M5000=SMALL(_xlfn.UNIQUE(FATURAS!M2:M5000),2))*FATURAS!AV2:AV5000*IF(ISNUMBER(FATURAS!BN2:BN5000),1+(FATURAS!BN2:BN5000/100),1))} -> 26.61925
A39: Faturas Disponíveis | B39: Ausência de faturas no período dos últimos 12 meses analisados | D39: =IFERROR(TEXT(SMALL(_xlfn.UNIQUE(FATURAS!M:M),3),"MMM/AA"),"") -> out/25 | E39: =SUMIFS(FATURAS!AQ:AQ, FATURAS!M:M, SMALL(_xlfn.UNIQUE(FATURAS!M:M),3)) -> 92.14 | F39: =SUMIFS(FATURAS!AR:AR, FATURAS!M:M, SMALL(_xlfn.UNIQUE(FATURAS!M:M),3)) -> 2113.14 | G39: =SUM(E39+F39) -> 2205.28 | H39: {=SUMPRODUCT( (FATURAS!M2:M5000=SMALL(_xlfn.UNIQUE(FATURAS!M2:M5000),3))* FATURAS!AU2:AU5000* IF(ISNUMBER(FATURAS!BN2:BN5000),1+(FATURAS!BN2:BN5000/100),1))} -> 2.6035 | I39: {=SUMPRODUCT((FATURAS!M2:M5000=SMALL(_xlfn.UNIQUE(FATURAS!M2:M5000),3))*FATURAS!AV2:AV5000*IF(ISNUMBER(FATURAS!BN2:BN5000),1+(FATURAS!BN2:BN5000/100),1))} -> 29.96075
D40: =IFERROR(TEXT(SMALL(_xlfn.UNIQUE(FATURAS!M:M),4),"MMM/AA"),"") -> nov/25 | E40: =SUMIFS(FATURAS!AQ:AQ, FATURAS!M:M, SMALL(_xlfn.UNIQUE(FATURAS!M:M),4)) -> 74.97 | F40: =SUMIFS(FATURAS!AR:AR, FATURAS!M:M, SMALL(_xlfn.UNIQUE(FATURAS!M:M),4)) -> 3172.17 | G40: =SUM(E40+F40) -> 3247.14 | H40: {=SUMPRODUCT( (FATURAS!M2:M5000=SMALL(_xlfn.UNIQUE(FATURAS!M2:M5000),4))* FATURAS!AU2:AU5000* IF(ISNUMBER(FATURAS!BN2:BN5000),1+(FATURAS!BN2:BN5000/100),1))} -> 2.16275 | I40: {=SUMPRODUCT((FATURAS!M2:M5000=SMALL(_xlfn.UNIQUE(FATURAS!M2:M5000),4))*FATURAS!AV2:AV5000*IF(ISNUMBER(FATURAS!BN2:BN5000),1+(FATURAS!BN2:BN5000/100),1))} -> 35.22925
D41: =IFERROR(TEXT(SMALL(_xlfn.UNIQUE(FATURAS!M:M),5),"MMM/AA"),"") -> dez/25 | E41: =SUMIFS(FATURAS!AQ:AQ, FATURAS!M:M, SMALL(_xlfn.UNIQUE(FATURAS!M:M),5)) -> 82.05 | F41: =SUMIFS(FATURAS!AR:AR, FATURAS!M:M, SMALL(_xlfn.UNIQUE(FATURAS!M:M),5)) -> 3480.9 | G41: =SUM(E41+F41) -> 3562.95 | H41: {=SUMPRODUCT( (FATURAS!M2:M5000=SMALL(_xlfn.UNIQUE(FATURAS!M2:M5000),5))* FATURAS!AU2:AU5000* IF(ISNUMBER(FATURAS!BN2:BN5000),1+(FATURAS!BN2:BN5000/100),1))} -> 2.3575 | I41: {=SUMPRODUCT((FATURAS!M2:M5000=SMALL(_xlfn.UNIQUE(FATURAS!M2:M5000),5))*FATURAS!AV2:AV5000*IF(ISNUMBER(FATURAS!BN2:BN5000),1+(FATURAS!BN2:BN5000/100),1))} -> 34.0505
D42: =IFERROR(TEXT(SMALL(_xlfn.UNIQUE(FATURAS!M:M),6),"MMM/AA"),"") -> jan/26 | E42: =SUMIFS(FATURAS!AQ:AQ, FATURAS!M:M, SMALL(_xlfn.UNIQUE(FATURAS!M:M),6)) -> 86.34 | F42: =SUMIFS(FATURAS!AR:AR, FATURAS!M:M, SMALL(_xlfn.UNIQUE(FATURAS!M:M),6)) -> 2788.41 | G42: =SUM(E42+F42) -> 2874.75 | H42: {=SUMPRODUCT( (FATURAS!M2:M5000=SMALL(_xlfn.UNIQUE(FATURAS!M2:M5000),6))* FATURAS!AU2:AU5000* IF(ISNUMBER(FATURAS!BN2:BN5000),1+(FATURAS!BN2:BN5000/100),1))} -> 2.75725 | I42: {=SUMPRODUCT((FATURAS!M2:M5000=SMALL(_xlfn.UNIQUE(FATURAS!M2:M5000),6))*FATURAS!AV2:AV5000*IF(ISNUMBER(FATURAS!BN2:BN5000),1+(FATURAS!BN2:BN5000/100),1))} -> 34.8295
D43: =IFERROR(TEXT(SMALL(_xlfn.UNIQUE(FATURAS!M:M),7),"MMM/AA"),"") -> fev/26 | E43: =SUMIFS(FATURAS!AQ:AQ, FATURAS!M:M, SMALL(_xlfn.UNIQUE(FATURAS!M:M),7)) -> 50.19 | F43: =SUMIFS(FATURAS!AR:AR, FATURAS!M:M, SMALL(_xlfn.UNIQUE(FATURAS!M:M),7)) -> 997.53 | G43: =SUM(E43+F43) -> 1047.72 | H43: {=SUMPRODUCT( (FATURAS!M2:M5000=SMALL(_xlfn.UNIQUE(FATURAS!M2:M5000),7))* FATURAS!AU2:AU5000* IF(ISNUMBER(FATURAS!BN2:BN5000),1+(FATURAS!BN2:BN5000/100),1))} -> 1.23 | I43: {=SUMPRODUCT((FATURAS!M2:M5000=SMALL(_xlfn.UNIQUE(FATURAS!M2:M5000),7))*FATURAS!AV2:AV5000*IF(ISNUMBER(FATURAS!BN2:BN5000),1+(FATURAS!BN2:BN5000/100),1))} -> 12.00275
D44: =IFERROR(TEXT(SMALL(_xlfn.UNIQUE(FATURAS!M:M),8),"MMM/AA"),"") -> mar/26 | E44: =SUMIFS(FATURAS!AQ:AQ, FATURAS!M:M, SMALL(_xlfn.UNIQUE(FATURAS!M:M),8)) -> 82.92 | F44: =SUMIFS(FATURAS!AR:AR, FATURAS!M:M, SMALL(_xlfn.UNIQUE(FATURAS!M:M),8)) -> 3281.64 | G44: =SUM(E44+F44) -> 3364.56 | H44: {=SUMPRODUCT( (FATURAS!M2:M5000=SMALL(_xlfn.UNIQUE(FATURAS!M2:M5000),8))* FATURAS!AU2:AU5000* IF(ISNUMBER(FATURAS!BN2:BN5000),1+(FATURAS!BN2:BN5000/100),1))} -> 2.3575 | I44: {=SUMPRODUCT((FATURAS!M2:M5000=SMALL(_xlfn.UNIQUE(FATURAS!M2:M5000),8))*FATURAS!AV2:AV5000*IF(ISNUMBER(FATURAS!BN2:BN5000),1+(FATURAS!BN2:BN5000/100),1))} -> 34.932
D45: Sem Histórico Disponível | E45: =SUMIFS(FATURAS!AQ:AQ, FATURAS!M:M, SMALL(_xlfn.UNIQUE(FATURAS!M:M),9)) -> 0 | F45: =SUMIFS(FATURAS!AR:AR, FATURAS!M:M, SMALL(_xlfn.UNIQUE(FATURAS!M:M),9)) -> 0 | G45: =SUM(E45+F45) -> 0 | H45: {=SUMPRODUCT( (FATURAS!M2:M5000=SMALL(_xlfn.UNIQUE(FATURAS!M2:M5000),9))* FATURAS!AU2:AU5000* IF(ISNUMBER(FATURAS!BN2:BN5000),1+(FATURAS!BN2:BN5000/100),1))} -> #NUM! | I45: {=SUMPRODUCT((FATURAS!M2:M5000=SMALL(_xlfn.UNIQUE(FATURAS!M2:M5000),9))*FATURAS!AV2:AV5000*IF(ISNUMBER(FATURAS!BN2:BN5000),1+(FATURAS!BN2:BN5000/100),1))} -> #NUM!
D46: Sem Histórico Disponível | E46: =SUMIFS(FATURAS!AQ:AQ, FATURAS!M:M, SMALL(_xlfn.UNIQUE(FATURAS!M:M),10)) -> 0 | F46: =SUMIFS(FATURAS!AR:AR, FATURAS!M:M, SMALL(_xlfn.UNIQUE(FATURAS!M:M),10)) -> 0 | G46: =SUM(E46+F46) -> 0 | H46: {=SUMPRODUCT( (FATURAS!M2:M5000=SMALL(_xlfn.UNIQUE(FATURAS!M2:M5000),10))* FATURAS!AU2:AU5000* IF(ISNUMBER(FATURAS!BN2:BN5000),1+(FATURAS!BN2:BN5000/100),1))} -> #NUM! | I46: {=SUMPRODUCT((FATURAS!M2:M5000=SMALL(_xlfn.UNIQUE(FATURAS!M2:M5000),10))*FATURAS!AV2:AV5000*IF(ISNUMBER(FATURAS!BN2:BN5000),1+(FATURAS!BN2:BN5000/100),1))} -> #NUM!
D47: Sem Histórico Disponível | E47: =SUMIFS(FATURAS!AQ:AQ, FATURAS!M:M, SMALL(_xlfn.UNIQUE(FATURAS!M:M),11)) -> 0 | F47: =SUMIFS(FATURAS!AR:AR, FATURAS!M:M, SMALL(_xlfn.UNIQUE(FATURAS!M:M),11)) -> 0 | G47: =SUM(E47+F47) -> 0 | H47: {=SUMPRODUCT( (FATURAS!M2:M5000=SMALL(_xlfn.UNIQUE(FATURAS!M2:M5000),11))* FATURAS!AU2:AU5000* IF(ISNUMBER(FATURAS!BN2:BN5000),1+(FATURAS!BN2:BN5000/100),1))} -> #NUM! | I47: {=SUMPRODUCT((FATURAS!M2:M5000=SMALL(_xlfn.UNIQUE(FATURAS!M2:M5000),11))*FATURAS!AV2:AV5000*IF(ISNUMBER(FATURAS!BN2:BN5000),1+(FATURAS!BN2:BN5000/100),1))} -> #NUM!
D48: Sem Histórico Disponível | E48: =SUMIFS(FATURAS!AQ:AQ, FATURAS!M:M, SMALL(_xlfn.UNIQUE(FATURAS!M:M),12)) -> 0 | F48: =SUMIFS(FATURAS!AR:AR, FATURAS!M:M, SMALL(_xlfn.UNIQUE(FATURAS!M:M),12)) -> 0 | G48: =SUM(E48+F48) -> 0 | H48: {=SUMPRODUCT( (FATURAS!M2:M5000=SMALL(_xlfn.UNIQUE(FATURAS!M2:M5000),12))* FATURAS!AU2:AU5000* IF(ISNUMBER(FATURAS!BN2:BN5000),1+(FATURAS!BN2:BN5000/100),1))} -> #NUM! | I48: {=SUMPRODUCT((FATURAS!M2:M5000=SMALL(_xlfn.UNIQUE(FATURAS!M2:M5000),12))*FATURAS!AV2:AV5000*IF(ISNUMBER(FATURAS!BN2:BN5000),1+(FATURAS!BN2:BN5000/100),1))} -> #NUM!
D49: TOTAIS | G49: =SUM(G37:G48) -> 18742.48
G50: =G49/1000 -> 18.74248

Sheet Sistemas de Cond. Ambiental
A1: UNIDADE CONSUMIDORA | D1: SITUAÇÃO ATUAL | U1: SISTEMA PROPOSTO | AM1: RESULTADOS ESPERADOS | AP1: RESULTADO AUTOMAÇÃO (10%) | AQ1: AUTOMAÇÃO + TROCA DE EQUIPAMENTO
A2: Unidade consumidora (Número da conta contrato) | B2: Pavimento | C2: Ambiente | D2: Descrição do sistema | E2: Tipo de equipamento / tecnologia | F2: Classificação Inmetro | G2: Potência nominal de refrigeração (BTU/h) | H2: Coefiente de eficiência energética (W/W) | I2: Quantidade | J2: Potência instalada (kW) | K2: Fator de utilização | L2: Potência média utilizada (kW) | M2: Funcionamento (h/dia) | N2: Funcionamento (h/ano) | O2: Meses no ano, de utilização do Sistema | P2: Dias úteis no mês, de utilização do Sistema | Q2: Horas por dia, de utilização do Sistema no horário de Ponta (horas) | R2: Fator de coincidência na ponta | S2: Energia consumida (MWh/ano) | T2: Demanda média na ponta (kW) | U2: Tipo de equipamento / tecnologia | V2: Classificação Inmetro | W2: Potência nominal de refrigeração (BTU/h) | X2: Coefiente de eficiência energética (W/W) | Y2: Preço Unitário (R$) | Z2: Quantidade | AA2: Potência instalada (kW) | AB2: Fator de utilização | AC2: Potência média utilizada (kW) | AD2: Funcionamento (h/dia) | AE2: Funcionamento (h/ano) | AF2: Meses no ano, de utilização do Sistema no horário de Ponta (meses) | AG2: Dias úteis no mês, de utilização do Sistema no horário de Ponta (dia) | AH2: Horas por dia, de utilização do Sistema no horário de Ponta (horas) | AI2: Fator de coincidência na ponta | AJ2: Energia consumida (MWh/ano) | AK2: Demanda média na ponta (kW) | AL2: Redução de demanda na ponta (kW) | AM2: Energia economizada (MWh/ano) | AN2: Investimento (R$) | AO2: Redução de consumo proposto em relação ao consumo total da UC (%) | AP2: Energia economizada (MWh/ano) | AQ2: Energia economizada (MWh/ano)
A3: =IF(UC_DADOS!$B$2=0,"",UC_DADOS!$B$2) -> 7041435180 | C3: Secretaria | D3: Argatto | E3: Split Hi-Wall | F3: E | G3: 12000 | H3: 3.5 | I3: 1 | J3: =IF(H3=0,0,((G3*0.293*I3)/(1000*H3))) -> 1.0045714 | K3: 0.7 | L3: =J3*K3 -> 0.7032 | M3: 8 | N3: =M3*O3*P3 -> 2040 | O3: 12 | P3: 21.25 | Q3: 0 | R3: =O3*P3*Q3/765 -> 0 | S3: =N3*L3/1000 -> 1.434528 | T3: =R3*L3 -> 0 | U3: {=IF(F3="A",E3,IFERROR(INDEX('EQUIPAMENTOS_EFICIENTES (BDD)'!G:G,MATCH(1,('EQUIPAMENTOS_EFICIENTES (BDD)'!G:G=E3)*('EQUIPAMENTOS_EFICIENTES (BDD)'!I:I=_xlfn.MINIFS('EQUIPAMENTOS_EFICIENTES (BDD)'!I:I,'EQUIPAMENTOS_EFICIENTES (BDD)'!G:G,E3,'EQUIPAMENTOS_EFICIENTES (BDD)'!I:I,">="&G3)),0)),"Substituição não encontrada"))} -> Split Hi-Wall | V3: {=IF(F3="A",F3,IFERROR(INDEX('EQUIPAMENTOS_EFICIENTES (BDD)'!H:H,MATCH(1,('EQUIPAMENTOS_EFICIENTES (BDD)'!G:G=E3)*('EQUIPAMENTOS_EFICIENTES (BDD)'!I:I=_xlfn.MINIFS('EQUIPAMENTOS_EFICIENTES (BDD)'!I:I,'EQUIPAMENTOS_EFICIENTES (BDD)'!G:G,E3,'EQUIPAMENTOS_EFICIENTES (BDD)'!I:I,">="&G3)),0)),"Substituição não encontrada"))} -> A | W3: {=IF(F3="A",G3,IFERROR(INDEX('EQUIPAMENTOS_EFICIENTES (BDD)'!I:I,MATCH(1,('EQUIPAMENTOS_EFICIENTES (BDD)'!G:G=E3)*('EQUIPAMENTOS_EFICIENTES (BDD)'!I:I=_xlfn.MINIFS('EQUIPAMENTOS_EFICIENTES (BDD)'!I:I,'EQUIPAMENTOS_EFICIENTES (BDD)'!G:G,E3,'EQUIPAMENTOS_EFICIENTES (BDD)'!I:I,">="&G3)),0)),"Substituição não encontrada"))} -> 12000 | X3: {=IF(F3="A",H3,IFERROR(INDEX('EQUIPAMENTOS_EFICIENTES (BDD)'!J:J,MATCH(1,('EQUIPAMENTOS_EFICIENTES (BDD)'!G:G=E3)*('EQUIPAMENTOS_EFICIENTES (BDD)'!I:I=_xlfn.MINIFS('EQUIPAMENTOS_EFICIENTES (BDD)'!I:I,'EQUIPAMENTOS_EFICIENTES (BDD)'!G:G,E3,'EQUIPAMENTOS_EFICIENTES (BDD)'!I:I,">="&G3)),0)),"Substituição não encontrada"))} -> 8.3 | Y3: {=IFERROR(INDEX('EQUIPAMENTOS_EFICIENTES (BDD)'!K:K,MATCH(1,('EQUIPAMENTOS_EFICIENTES (BDD)'!G:G=E3)*('EQUIPAMENTOS_EFICIENTES (BDD)'!I:I=_xlfn.MINIFS('EQUIPAMENTOS_EFICIENTES (BDD)'!I:I,'EQUIPAMENTOS_EFICIENTES (BDD)'!G:G,E3,'EQUIPAMENTOS_EFICIENTES (BDD)'!I:I,">="&G3)),0)),"")} -> 3583 | Z3: =I3 -> 1 | AA3: =IF(X3=0,0,((W3*0.293*Z3)/(1000*X3))) -> 0.42361446 | AB3: =K3 -> 0.7 | AC3: =AA3*AB3 -> 0.29653012 | AD3: =M3 -> 8 | AE3: =N3 -> 2040 | AF3: =O3 -> 12 | AG3: =P3 -> 21.25 | AH3: =Q3 -> 0 | AI3: =R3 -> 0 | AJ3: =AC3*AE3/1000 -> 0.60492145 | AK3: =AI3*AC3 -> 0 | AL3: =T3-AK3 -> 0 | AM3: =S3-AJ3 -> 0.82960655 | AN3: =IF(AM3<>0,Y3*Z3,0) -> 3583 | AO3: =AM3/478.332 -> 0.0017343739 | AP3: =S3*0.9 -> 1.2910752 | AQ3: =AJ3*0.9 -> 0.5444293
A4: =IF(UC_DADOS!$B$2=0,"",UC_DADOS!$B$2) -> 7041435180 | C4: Direção | D4: Argatto | E4: Split Hi-Wall | F4: E | G4: 12000 | H4: 3.5 | I4: 1 | J4: =IF(H4=0,0,((G4*0.293*I4)/(1000*H4))) -> 1.0045714 | K4: 0.7 | L4: =J4*K4 -> 0.7032 | M4: 8 | N4: =M4*O4*P4 -> 2040 | O4: 12 | P4: 21.25 | Q4: 0 | R4: =O4*P4*Q4/765 -> 0 | S4: =N4*L4/1000 -> 1.434528 | T4: =R4*L4 -> 0 | U4: {=IF(F4="A",E4,IFERROR(INDEX('EQUIPAMENTOS_EFICIENTES (BDD)'!G:G,MATCH(1,('EQUIPAMENTOS_EFICIENTES (BDD)'!G:G=E4)*('EQUIPAMENTOS_EFICIENTES (BDD)'!I:I=_xlfn.MINIFS('EQUIPAMENTOS_EFICIENTES (BDD)'!I:I,'EQUIPAMENTOS_EFICIENTES (BDD)'!G:G,E4,'EQUIPAMENTOS_EFICIENTES (BDD)'!I:I,">="&G4)),0)),"Substituição não encontrada"))} -> Split Hi-Wall | V4: {=IF(F4="A",F4,IFERROR(INDEX('EQUIPAMENTOS_EFICIENTES (BDD)'!H:H,MATCH(1,('EQUIPAMENTOS_EFICIENTES (BDD)'!G:G=E4)*('EQUIPAMENTOS_EFICIENTES (BDD)'!I:I=_xlfn.MINIFS('EQUIPAMENTOS_EFICIENTES (BDD)'!I:I,'EQUIPAMENTOS_EFICIENTES (BDD)'!G:G,E4,'EQUIPAMENTOS_EFICIENTES (BDD)'!I:I,">="&G4)),0)),"Substituição não encontrada"))} -> A | W4: {=IF(F4="A",G4,IFERROR(INDEX('EQUIPAMENTOS_EFICIENTES (BDD)'!I:I,MATCH(1,('EQUIPAMENTOS_EFICIENTES (BDD)'!G:G=E4)*('EQUIPAMENTOS_EFICIENTES (BDD)'!I:I=_xlfn.MINIFS('EQUIPAMENTOS_EFICIENTES (BDD)'!I:I,'EQUIPAMENTOS_EFICIENTES (BDD)'!G:G,E4,'EQUIPAMENTOS_EFICIENTES (BDD)'!I:I,">="&G4)),0)),"Substituição não encontrada"))} -> 12000 | X4: {=IF(F4="A",H4,IFERROR(INDEX('EQUIPAMENTOS_EFICIENTES (BDD)'!J:J,MATCH(1,('EQUIPAMENTOS_EFICIENTES (BDD)'!G:G=E4)*('EQUIPAMENTOS_EFICIENTES (BDD)'!I:I=_xlfn.MINIFS('EQUIPAMENTOS_EFICIENTES (BDD)'!I:I,'EQUIPAMENTOS_EFICIENTES (BDD)'!G:G,E4,'EQUIPAMENTOS_EFICIENTES (BDD)'!I:I,">="&G4)),0)),"Substituição não encontrada"))} -> 8.3 | Y4: {=IFERROR(INDEX('EQUIPAMENTOS_EFICIENTES (BDD)'!K:K,MATCH(1,('EQUIPAMENTOS_EFICIENTES (BDD)'!G:G=E4)*('EQUIPAMENTOS_EFICIENTES (BDD)'!I:I=_xlfn.MINIFS('EQUIPAMENTOS_EFICIENTES (BDD)'!I:I,'EQUIPAMENTOS_EFICIENTES (BDD)'!G:G,E4,'EQUIPAMENTOS_EFICIENTES (BDD)'!I:I,">="&G4)),0)),"")} -> 3583 | Z4: =I4 -> 1 | AA4: =IF(X4=0,0,((W4*0.293*Z4)/(1000*X4))) -> 0.42361446 | AB4: =K4 -> 0.7 | AC4: =AA4*AB4 -> 0.29653012 | AD4: =M4 -> 8 | AE4: =N4 -> 2040 | AF4: =O4 -> 12 | AG4: =P4 -> 21.25 | AH4: =Q4 -> 0 | AI4: =R4 -> 0 | AJ4: =AC4*AE4/1000 -> 0.60492145 | AK4: =AI4*AC4 -> 0 | AL4: =T4-AK4 -> 0 | AM4: =S4-AJ4 -> 0.82960655 | AN4: =IF(AM4<>0,Y4*Z4,0) -> 3583 | AO4: =AM4/478.332 -> 0.0017343739 | AP4: =S4*0.9 -> 1.2910752 | AQ4: =AJ4*0.9 -> 0.5444293
A5: =IF(UC_DADOS!$B$2=0,"",UC_DADOS!$B$2) -> 7041435180 | C5: Sala dos professores | D5: Argatto | E5: Split Hi-Wall | F5: E | G5: 12000 | H5: 3.5 | I5: 2 | J5: =IF(H5=0,0,((G5*0.293*I5)/(1000*H5))) -> 2.0091429 | K5: 0.7 | L5: =J5*K5 -> 1.4064 | M5: 4 | N5: =M5*O5*P5 -> 1020 | O5: 12 | P5: 21.25 | Q5: 0 | R5: =O5*P5*Q5/765 -> 0 | S5: =N5*L5/1000 -> 1.434528 | T5: =R5*L5 -> 0 | U5: {=IF(F5="A",E5,IFERROR(INDEX('EQUIPAMENTOS_EFICIENTES (BDD)'!G:G,MATCH(1,('EQUIPAMENTOS_EFICIENTES (BDD)'!G:G=E5)*('EQUIPAMENTOS_EFICIENTES (BDD)'!I:I=_xlfn.MINIFS('EQUIPAMENTOS_EFICIENTES (BDD)'!I:I,'EQUIPAMENTOS_EFICIENTES (BDD)'!G:G,E5,'EQUIPAMENTOS_EFICIENTES (BDD)'!I:I,">="&G5)),0)),"Substituição não encontrada"))} -> Split Hi-Wall | V5: {=IF(F5="A",F5,IFERROR(INDEX('EQUIPAMENTOS_EFICIENTES (BDD)'!H:H,MATCH(1,('EQUIPAMENTOS_EFICIENTES (BDD)'!G:G=E5)*('EQUIPAMENTOS_EFICIENTES (BDD)'!I:I=_xlfn.MINIFS('EQUIPAMENTOS_EFICIENTES (BDD)'!I:I,'EQUIPAMENTOS_EFICIENTES (BDD)'!G:G,E5,'EQUIPAMENTOS_EFICIENTES (BDD)'!I:I,">="&G5)),0)),"Substituição não encontrada"))} -> A | W5: {=IF(F5="A",G5,IFERROR(INDEX('EQUIPAMENTOS_EFICIENTES (BDD)'!I:I,MATCH(1,('EQUIPAMENTOS_EFICIENTES (BDD)'!G:G=E5)*('EQUIPAMENTOS_EFICIENTES (BDD)'!I:I=_xlfn.MINIFS('EQUIPAMENTOS_EFICIENTES (BDD)'!I:I,'EQUIPAMENTOS_EFICIENTES (BDD)'!G:G,E5,'EQUIPAMENTOS_EFICIENTES (BDD)'!I:I,">="&G5)),0)),"Substituição não encontrada"))} -> 12000 | X5: {=IF(F5="A",H5,IFERROR(INDEX('EQUIPAMENTOS_EFICIENTES (BDD)'!J:J,MATCH(1,('EQUIPAMENTOS_EFICIENTES (BDD)'!G:G=E5)*('EQUIPAMENTOS_EFICIENTES (BDD)'!I:I=_xlfn.MINIFS('EQUIPAMENTOS_EFICIENTES (BDD)'!I:I,'EQUIPAMENTOS_EFICIENTES (BDD)'!G:G,E5,'EQUIPAMENTOS_EFICIENTES (BDD)'!I:I,">="&G5)),0)),"Substituição não encontrada"))} -> 8.3 | Y5: {=IFERROR(INDEX('EQUIPAMENTOS_EFICIENTES (BDD)'!K:K,MATCH(1,('EQUIPAMENTOS_EFICIENTES (BDD)'!G:G=E5)*('EQUIPAMENTOS_EFICIENTES (BDD)'!I:I=_xlfn.MINIFS('EQUIPAMENTOS_EFICIENTES (BDD)'!I:I,'EQUIPAMENTOS_EFICIENTES (BDD)'!G:G,E5,'EQUIPAMENTOS_EFICIENTES (BDD)'!I:I,">="&G5)),0)),"")} -> 3583 | Z5: =I5 -> 2 | AA5: =IF(X5=0,0,((W5*0.293*Z5)/(1000*X5))) -> 0.84722892 | AB5: =K5 -> 0.7 | AC5: =AA5*AB5 -> 0.59306024 | AD5: =M5 -> 4 | AE5: =N5 -> 1020 | AF5: =O5 -> 12 | AG5: =P5 -> 21.25 | AH5: =Q5 -> 0 | AI5: =R5 -> 0 | AJ5: =AC5*AE5/1000 -> 0.60492145 | AK5: =AI5*AC5 -> 0 | AL5: =T5-AK5 -> 0 | AM5: =S5-AJ5 -> 0.82960655 | AN5: =IF(AM5<>0,Y5*Z5,0) -> 7166 | AO5: =AM5/478.332 -> 0.0017343739 | AP5: =S5*0.9 -> 1.2910752 | AQ5: =AJ5*0.9 -> 0.5444293
A6: =IF(UC_DADOS!$B$2=0,"",UC_DADOS!$B$2) -> 7041435180 | C6: Salas de aula (01 a 07) | D6: Philco | E6: Split Piso Teto | F6: A | G6: 36000 | H6: 5.5 | I6: 7 | J6: =IF(H6=0,0,((G6*0.293*I6)/(1000*H6))) -> 13.424727 | K6: 0.7 | L6: =J6*K6 -> 9.3973091 | M6: 8 | N6: =M6*O6*P6 -> 1870 | O6: 11 | P6: 21.25 | Q6: 0 | R6: =O6*P6*Q6/765 -> 0 | S6: =N6*L6/1000 -> 17.572968 | T6: =R6*L6 -> 0 | U6: {=IF(F6="A",E6,IFERROR(INDEX('EQUIPAMENTOS_EFICIENTES (BDD)'!G:G,MATCH(1,('EQUIPAMENTOS_EFICIENTES (BDD)'!G:G=E6)*('EQUIPAMENTOS_EFICIENTES (BDD)'!I:I=_xlfn.MINIFS('EQUIPAMENTOS_EFICIENTES (BDD)'!I:I,'EQUIPAMENTOS_EFICIENTES (BDD)'!G:G,E6,'EQUIPAMENTOS_EFICIENTES (BDD)'!I:I,">="&G6)),0)),"Substituição não encontrada"))} -> Split Piso Teto | V6: {=IF(F6="A",F6,IFERROR(INDEX('EQUIPAMENTOS_EFICIENTES (BDD)'!H:H,MATCH(1,('EQUIPAMENTOS_EFICIENTES (BDD)'!G:G=E6)*('EQUIPAMENTOS_EFICIENTES (BDD)'!I:I=_xlfn.MINIFS('EQUIPAMENTOS_EFICIENTES (BDD)'!I:I,'EQUIPAMENTOS_EFICIENTES (BDD)'!G:G,E6,'EQUIPAMENTOS_EFICIENTES (BDD)'!I:I,">="&G6)),0)),"Substituição não encontrada"))} -> A | W6: {=IF(F6="A",G6,IFERROR(INDEX('EQUIPAMENTOS_EFICIENTES (BDD)'!I:I,MATCH(1,('EQUIPAMENTOS_EFICIENTES (BDD)'!G:G=E6)*('EQUIPAMENTOS_EFICIENTES (BDD)'!I:I=_xlfn.MINIFS('EQUIPAMENTOS_EFICIENTES (BDD)'!I:I,'EQUIPAMENTOS_EFICIENTES (BDD)'!G:G,E6,'EQUIPAMENTOS_EFICIENTES (BDD)'!I:I,">="&G6)),0)),"Substituição não encontrada"))} -> 36000 | X6: {=IF(F6="A",H6,IFERROR(INDEX('EQUIPAMENTOS_EFICIENTES (BDD)'!J:J,MATCH(1,('EQUIPAMENTOS_EFICIENTES (BDD)'!G:G=E6)*('EQUIPAMENTOS_EFICIENTES (BDD)'!I:I=_xlfn.MINIFS('EQUIPAMENTOS_EFICIENTES (BDD)'!I:I,'EQUIPAMENTOS_EFICIENTES (BDD)'!G:G,E6,'EQUIPAMENTOS_EFICIENTES (BDD)'!I:I,">="&G6)),0)),"Substituição não encontrada"))} -> 5.5 | Y6: {=IFERROR(INDEX('EQUIPAMENTOS_EFICIENTES (BDD)'!K:K,MATCH(1,('EQUIPAMENTOS_EFICIENTES (BDD)'!G:G=E6)*('EQUIPAMENTOS_EFICIENTES (BDD)'!I:I=_xlfn.MINIFS('EQUIPAMENTOS_EFICIENTES (BDD)'!I:I,'EQUIPAMENTOS_EFICIENTES (BDD)'!G:G,E6,'EQUIPAMENTOS_EFICIENTES (BDD)'!I:I,">="&G6)),0)),"")} -> 8299 | Z6: =I6 -> 7 | AA6: =IF(X6=0,0,((W6*0.293*Z6)/(1000*X6))) -> 13.424727 | AB6: =K6 -> 0.7 | AC6: =AA6*AB6 -> 9.3973091 | AD6: =M6 -> 8 | AE6: =N6 -> 1870 | AF6: =O6 -> 11 | AG6: =P6 -> 21.25 | AH6: =Q6 -> 0 | AI6: =R6 -> 0 | AJ6: =AC6*AE6/1000 -> 17.572968 | AK6: =AI6*AC6 -> 0 | AL6: =T6-AK6 -> 0 | AM6: =S6-AJ6 -> 0 | AN6: =IF(AM6<>0,Y6*Z6,0) -> 0 | AO6: =AM6/478.332 -> 0 | AP6: =S6*0.9 -> 15.815671 | AQ6: =AJ6*0.9 -> 15.815671
A7: =IF(UC_DADOS!$B$2=0,"",UC_DADOS!$B$2) -> 7041435180 | C7: Salas 10 a 14 | D7: Philco | E7: Split Piso Teto | F7: A | G7: 36000 | H7: 5.5 | I7: 5 | J7: =IF(H7=0,0,((G7*0.293*I7)/(1000*H7))) -> 9.5890909 | K7: 0.7 | L7: =J7*K7 -> 6.7123636 | M7: 8 | N7: =M7*O7*P7 -> 1870 | O7: 11 | P7: 21.25 | Q7: 0 | R7: =O7*P7*Q7/765 -> 0 | S7: =N7*L7/1000 -> 12.55212 | T7: =R7*L7 -> 0 | U7: {=IF(F7="A",E7,IFERROR(INDEX('EQUIPAMENTOS_EFICIENTES (BDD)'!G:G,MATCH(1,('EQUIPAMENTOS_EFICIENTES (BDD)'!G:G=E7)*('EQUIPAMENTOS_EFICIENTES (BDD)'!I:I=_xlfn.MINIFS('EQUIPAMENTOS_EFICIENTES (BDD)'!I:I,'EQUIPAMENTOS_EFICIENTES (BDD)'!G:G,E7,'EQUIPAMENTOS_EFICIENTES (BDD)'!I:I,">="&G7)),0)),"Substituição não encontrada"))} -> Split Piso Teto | V7: {=IF(F7="A",F7,IFERROR(INDEX('EQUIPAMENTOS_EFICIENTES (BDD)'!H:H,MATCH(1,('EQUIPAMENTOS_EFICIENTES (BDD)'!G:G=E7)*('EQUIPAMENTOS_EFICIENTES (BDD)'!I:I=_xlfn.MINIFS('EQUIPAMENTOS_EFICIENTES (BDD)'!I:I,'EQUIPAMENTOS_EFICIENTES (BDD)'!G:G,E7,'EQUIPAMENTOS_EFICIENTES (BDD)'!I:I,">="&G7)),0)),"Substituição não encontrada"))} -> A | W7: {=IF(F7="A",G7,IFERROR(INDEX('EQUIPAMENTOS_EFICIENTES (BDD)'!I:I,MATCH(1,('EQUIPAMENTOS_EFICIENTES (BDD)'!G:G=E7)*('EQUIPAMENTOS_EFICIENTES (BDD)'!I:I=_xlfn.MINIFS('EQUIPAMENTOS_EFICIENTES (BDD)'!I:I,'EQUIPAMENTOS_EFICIENTES (BDD)'!G:G,E7,'EQUIPAMENTOS_EFICIENTES (BDD)'!I:I,">="&G7)),0)),"Substituição não encontrada"))} -> 36000 | X7: {=IF(F7="A",H7,IFERROR(INDEX('EQUIPAMENTOS_EFICIENTES (BDD)'!J:J,MATCH(1,('EQUIPAMENTOS_EFICIENTES (BDD)'!G:G=E7)*('EQUIPAMENTOS_EFICIENTES (BDD)'!I:I=_xlfn.MINIFS('EQUIPAMENTOS_EFICIENTES (BDD)'!I:I,'EQUIPAMENTOS_EFICIENTES (BDD)'!G:G,E7,'EQUIPAMENTOS_EFICIENTES (BDD)'!I:I,">="&G7)),0)),"Substituição não encontrada"))} -> 5.5 | Y7: {=IFERROR(INDEX('EQUIPAMENTOS_EFICIENTES (BDD)'!K:K,MATCH(1,('EQUIPAMENTOS_EFICIENTES (BDD)'!G:G=E7)*('EQUIPAMENTOS_EFICIENTES (BDD)'!I:I=_xlfn.MINIFS('EQUIPAMENTOS_EFICIENTES (BDD)'!I:I,'EQUIPAMENTOS_EFICIENTES (BDD)'!G:G,E7,'EQUIPAMENTOS_EFICIENTES (BDD)'!I:I,">="&G7)),0)),"")} -> 8299 | Z7: =I7 -> 5 | AA7: =IF(X7=0,0,((W7*0.293*Z7)/(1000*X7))) -> 9.5890909 | AB7: =K7 -> 0.7 | AC7: =AA7*AB7 -> 6.7123636 | AD7: =M7 -> 8 | AE7: =N7 -> 1870 | AF7: =O7 -> 11 | AG7: =P7 -> 21.25 | AH7: =Q7 -> 0 | AI7: =R7 -> 0 | AJ7: =AC7*AE7/1000 -> 12.55212 | AK7: =AI7*AC7 -> 0 | AL7: =T7-AK7 -> 0 | AM7: =S7-AJ7 -> 0 | AN7: =IF(AM7<>0,Y7*Z7,0) -> 0 | AO7: =AM7/478.332 -> 0 | AP7: =S7*0.9 -> 11.296908 | AQ7: =AJ7*0.9 -> 11.296908
A8: =IF(UC_DADOS!$B$2=0,"",UC_DADOS!$B$2) -> 7041435180 | C8: Refeitório | D8: Philco | E8: Split Piso Teto | F8: A | G8: 36000 | H8: 5.5 | I8: 3 | J8: =IF(H8=0,0,((G8*0.293*I8)/(1000*H8))) -> 5.7534545 | K8: 0.7 | L8: =J8*K8 -> 4.0274182 | M8: 4 | N8: =M8*O8*P8 -> 935 | O8: 11 | P8: 21.25 | Q8: 0 | R8: =O8*P8*Q8/765 -> 0 | S8: =N8*L8/1000 -> 3.765636 | T8: =R8*L8 -> 0 | U8: {=IF(F8="A",E8,IFERROR(INDEX('EQUIPAMENTOS_EFICIENTES (BDD)'!G:G,MATCH(1,('EQUIPAMENTOS_EFICIENTES (BDD)'!G:G=E8)*('EQUIPAMENTOS_EFICIENTES (BDD)'!I:I=_xlfn.MINIFS('EQUIPAMENTOS_EFICIENTES (BDD)'!I:I,'EQUIPAMENTOS_EFICIENTES (BDD)'!G:G,E8,'EQUIPAMENTOS_EFICIENTES (BDD)'!I:I,">="&G8)),0)),"Substituição não encontrada"))} -> Split Piso Teto | V8: {=IF(F8="A",F8,IFERROR(INDEX('EQUIPAMENTOS_EFICIENTES (BDD)'!H:H,MATCH(1,('EQUIPAMENTOS_EFICIENTES (BDD)'!G:G=E8)*('EQUIPAMENTOS_EFICIENTES (BDD)'!I:I=_xlfn.MINIFS('EQUIPAMENTOS_EFICIENTES (BDD)'!I:I,'EQUIPAMENTOS_EFICIENTES (BDD)'!G:G,E8,'EQUIPAMENTOS_EFICIENTES (BDD)'!I:I,">="&G8)),0)),"Substituição não encontrada"))} -> A | W8: {=IF(F8="A",G8,IFERROR(INDEX('EQUIPAMENTOS_EFICIENTES (BDD)'!I:I,MATCH(1,('EQUIPAMENTOS_EFICIENTES (BDD)'!G:G=E8)*('EQUIPAMENTOS_EFICIENTES (BDD)'!I:I=_xlfn.MINIFS('EQUIPAMENTOS_EFICIENTES (BDD)'!I:I,'EQUIPAMENTOS_EFICIENTES (BDD)'!G:G,E8,'EQUIPAMENTOS_EFICIENTES (BDD)'!I:I,">="&G8)),0)),"Substituição não encontrada"))} -> 36000 | X8: {=IF(F8="A",H8,IFERROR(INDEX('EQUIPAMENTOS_EFICIENTES (BDD)'!J:J,MATCH(1,('EQUIPAMENTOS_EFICIENTES (BDD)'!G:G=E8)*('EQUIPAMENTOS_EFICIENTES (BDD)'!I:I=_xlfn.MINIFS('EQUIPAMENTOS_EFICIENTES (BDD)'!I:I,'EQUIPAMENTOS_EFICIENTES (BDD)'!G:G,E8,'EQUIPAMENTOS_EFICIENTES (BDD)'!I:I,">="&G8)),0)),"Substituição não encontrada"))} -> 5.5 | Y8: {=IFERROR(INDEX('EQUIPAMENTOS_EFICIENTES (BDD)'!K:K,MATCH(1,('EQUIPAMENTOS_EFICIENTES (BDD)'!G:G=E8)*('EQUIPAMENTOS_EFICIENTES (BDD)'!I:I=_xlfn.MINIFS('EQUIPAMENTOS_EFICIENTES (BDD)'!I:I,'EQUIPAMENTOS_EFICIENTES (BDD)'!G:G,E8,'EQUIPAMENTOS_EFICIENTES (BDD)'!I:I,">="&G8)),0)),"")} -> 8299 | Z8: =I8 -> 3 | AA8: =IF(X8=0,0,((W8*0.293*Z8)/(1000*X8))) -> 5.7534545 | AB8: =K8 -> 0.7 | AC8: =AA8*AB8 -> 4.0274182 | AD8: =M8 -> 4 | AE8: =N8 -> 935 | AF8: =O8 -> 11 | AG8: =P8 -> 21.25 | AH8: =Q8 -> 0 | AI8: =R8 -> 0 | AJ8: =AC8*AE8/1000 -> 3.765636 | AK8: =AI8*AC8 -> 0 | AL8: =T8-AK8 -> 0 | AM8: =S8-AJ8 -> 0 | AN8: =IF(AM8<>0,Y8*Z8,0) -> 0 | AO8: =AM8/478.332 -> 0 | AP8: =S8*0.9 -> 3.3890724 | AQ8: =AJ8*0.9 -> 3.3890724
E9: TOTAL | I9: =SUM(I3:I8) -> 19 | J9: =SUM(J3:J8) -> 32.785558 | L9: =SUM(L3:L8) -> 22.949891 | S9: =SUM(S3:S8) -> 38.194308 | T9: =SUM(T3:T8) -> 0 | W9: TOTAL | Z9: =SUM(Z3:Z8) -> 19 | AA9: =SUM(Z3:Z8) -> 19 | AC9: =SUM(AC3:AC8) -> 21.323211 | AJ9: =SUM(AJ3:AJ8) -> 35.705488 | AK9: =SUM(AK3:AK8) -> 0 | AL9: =SUM(AL3:AL8) -> 0 | AM9: =SUM(AM3:AM8) -> 2.4888197 | AN9: =SUM(AN3:AN8) -> 14332 | AO9: =SUM(AO3:AO8) -> 0.0052031218 | AP9: =SUM(AP3:AP8) -> 34.374877 | AQ9: =SUM(AQ3:AQ8) -> 32.13494
AL87: TOTAL | AM87: =SUM(AM3:AM86) -> 4.9776393 | AO87: =SUM(AO3:AO86) -> 0.010406244

Sheet Sistemas de Refrigeração
A1: Unidade Consumidora | D1: SITUAÇÃO ATUAL | T1: SISTEMA PROPOSTO | AH1: RESULTADOS ESPERADOS
A2: Unidade consumidora (Número da conta contrato) | B2: Pavimento | C2: Ambiente | D2: Tipo de equipamento / tecnologia | E2: Porte | F2: Estado de Conservação | G2: Descrição do Sistema | H2: Potência nominal (W) | I2: Fator de utilização | J2: Potência média utilizada (kW) | K2: Quantidade | L2: Funcionamento (h/dia) | M2: Funcionamento (h/ano) | N2: Meses no ano, de utilização do Sistema | O2: Dias úteis no mês, de utilização do Sistema | P2: Horas por dia, de utilização do Sistema no horário de Ponta (horas) | Q2: Fator de coincidência na ponta | R2: Energia consumida (MWh/ano) | S2: Demanda média na ponta (kW) | T2: Tipo de equipamento / tecnologia | U2: Porte | V2: Potência nominal (W) | W2: Fator de utilização | X2: Potência média utilizada (W) | Y2: Quantidade | Z2: Preço Unitário (R$) | AA2: Funcionamento (h/ano) | AB2: Meses no ano, de utilização do Sistema no horário de Ponta (meses) | AC2: Dias úteis no mês, de utilização do Sistema no horário de Ponta (dias) | AD2: Horas por dia, de utilização do Sistema no horário de Ponta (horas) | AE2: Fator de coincidência na ponta | AF2: Energia consumida (MWh/ano) | AG2: Demanda média na ponta (kW) | AH2: Redução de demanda na ponta (kW) | AI2: Energia economizada (MWh/ano) | AJ2: Investimento (R$) | AK2: Redução de consumo proposto em relação ao consumo total da UC (%)
A3: =IF(UC_DADOS!$B$2=0,"",UC_DADOS!$B$2) -> 7041435180 | B3: Térreo | C3: Cozinha | D3: Freezer Horizontal | E3: Grande | F3: Bom | G3: Freezers | H3: 180 | I3: 0.5 | J3: =(H3*I3)/1000 -> 0.09 | K3: 1 | L3: 24 | M3: =L3*N3*O3 -> 8640 | N3: 12 | O3: 30 | P3: 3 | Q3: =N3*O3*P3/765 -> 1.4117647 | R3: =(J3*M3)/1000 -> 0.7776 | S3: =J3*Q3 -> 0.12705882 | T3: {=IF(F3="Ruim",IFERROR(INDEX('EQUIPAMENTOS_EFICIENTES (BDD)'!O:O,MATCH(1,('EQUIPAMENTOS_EFICIENTES (BDD)'!O:O=D3)*('EQUIPAMENTOS_EFICIENTES (BDD)'!T:T=E3),0)),""),D3)} -> Freezer Horizontal | U3: =E3 -> Grande | V3: {=IF(F3="Ruim",IFERROR(INDEX('EQUIPAMENTOS_EFICIENTES (BDD)'!Q:Q,MATCH(1,('EQUIPAMENTOS_EFICIENTES (BDD)'!O:O=D3)*('EQUIPAMENTOS_EFICIENTES (BDD)'!T:T=E3),0)),H3),H3)} -> 180 | W3: 0.45 | X3: =(W3*V3)/1000 -> 0.081 | Y3: =K3 -> 1 | Z3: {=IF(F3="Ruim",IFERROR(INDEX('EQUIPAMENTOS_EFICIENTES (BDD)'!U:U,MATCH(1,('EQUIPAMENTOS_EFICIENTES (BDD)'!O:O=D3)*('EQUIPAMENTOS_EFICIENTES (BDD)'!T:T=E3),0)),0),0)} -> 0 | AA3: =M3 -> 8640 | AB3: =N3 -> 12 | AC3: =O3 -> 30 | AD3: =P3 -> 3 | AE3: =Q3 -> 1.4117647 | AF3: =(AA3*X3)/1000 -> 0.69984 | AG3: =AE3*X3/1000 -> 0.00011435294 | AH3: =S3-AG3 -> 0.12694447 | AI3: =(R3-AF3) -> 0.07776 | AJ3: =IF(AI3>0,Y3*Z3,0) -> 0 | AK3: =AI3/478.332 -> 0.00016256491
A4: =IF(UC_DADOS!$B$2=0,"",UC_DADOS!$B$2) -> 7041435180 | B4: Térreo | C4: Cozinha | D4: Geladeira | E4: Grande | F4: Bom | G4: Refrigeradores | H4: 150 | I4: 0.45 | J4: =(H4*I4)/1000 -> 0.0675 | K4: 1 | L4: 24 | M4: =L4*N4*O4 -> 8640 | N4: 12 | O4: 30 | P4: 3 | Q4: =N4*O4*P4/765 -> 1.4117647 | R4: =(J4*M4)/1000 -> 0.5832 | S4: =J4*Q4 -> 0.095294118 | T4: {=IF(F4="Ruim",IFERROR(INDEX('EQUIPAMENTOS_EFICIENTES (BDD)'!O:O,MATCH(1,('EQUIPAMENTOS_EFICIENTES (BDD)'!O:O=D4)*('EQUIPAMENTOS_EFICIENTES (BDD)'!T:T=E4),0)),""),D4)} -> Geladeira | U4: =E4 -> Grande | V4: {=IF(F4="Ruim",IFERROR(INDEX('EQUIPAMENTOS_EFICIENTES (BDD)'!Q:Q,MATCH(1,('EQUIPAMENTOS_EFICIENTES (BDD)'!O:O=D4)*('EQUIPAMENTOS_EFICIENTES (BDD)'!T:T=E4),0)),H4),H4)} -> 150 | W4: {=IF(F4="Ruim",IFERROR(INDEX('EQUIPAMENTOS_EFICIENTES (BDD)'!S:S,MATCH(1,('EQUIPAMENTOS_EFICIENTES (BDD)'!O:O=D4)*('EQUIPAMENTOS_EFICIENTES (BDD)'!T:T=E4),0)),I4),I4)} -> 0.45 | X4: =(W4*V4)/1000 -> 0.0675 | Y4: =K4 -> 1 | Z4: {=IF(F4="Ruim",IFERROR(INDEX('EQUIPAMENTOS_EFICIENTES (BDD)'!U:U,MATCH(1,('EQUIPAMENTOS_EFICIENTES (BDD)'!O:O=D4)*('EQUIPAMENTOS_EFICIENTES (BDD)'!T:T=E4),0)),0),0)} -> 0 | AA4: =M4 -> 8640 | AB4: =N4 -> 12 | AC4: =O4 -> 30 | AD4: =P4 -> 3 | AE4: =Q4 -> 1.4117647 | AF4: =(AA4*X4)/1000 -> 0.5832 | AG4: =AE4*X4/1000 -> 9.5294118e-05 | AH4: =S4-AG4 -> 0.095198824 | AI4: =(R4-AF4) -> 0 | AJ4: =IF(AI4>0,Y4*Z4,0) -> 0 | AK4: =AI4/478.332 -> 0
A5: =IF(UC_DADOS!$B$2=0,"",UC_DADOS!$B$2) -> 7041435180 | B5: Térreo | C5: Cozinha | D5: Geladeira | E5: Grande | F5: Bom | G5: Refrigeradores | H5: 160 | I5: 0.49 | J5: =(H5*I5)/1000 -> 0.0784 | K5: 1 | L5: 24 | M5: =L5*N5*O5 -> 8640 | N5: 12 | O5: 30 | P5: 3 | Q5: =N5*O5*P5/765 -> 1.4117647 | R5: =(J5*M5)/1000 -> 0.677376 | S5: =J5*Q5 -> 0.11068235 | T5: {=IF(F5="Ruim",IFERROR(INDEX('EQUIPAMENTOS_EFICIENTES (BDD)'!O:O,MATCH(1,('EQUIPAMENTOS_EFICIENTES (BDD)'!O:O=D5)*('EQUIPAMENTOS_EFICIENTES (BDD)'!T:T=E5),0)),""),D5)} -> Geladeira | U5: =E5 -> Grande | V5: {=IF(F5="Ruim",IFERROR(INDEX('EQUIPAMENTOS_EFICIENTES (BDD)'!Q:Q,MATCH(1,('EQUIPAMENTOS_EFICIENTES (BDD)'!O:O=D5)*('EQUIPAMENTOS_EFICIENTES (BDD)'!T:T=E5),0)),H5),H5)} -> 160 | W5: {=IF(F5="Ruim",IFERROR(INDEX('EQUIPAMENTOS_EFICIENTES (BDD)'!S:S,MATCH(1,('EQUIPAMENTOS_EFICIENTES (BDD)'!O:O=D5)*('EQUIPAMENTOS_EFICIENTES (BDD)'!T:T=E5),0)),I5),I5)} -> 0.49 | X5: =(W5*V5)/1000 -> 0.0784 | Y5: =K5 -> 1 | Z5: {=IF(F5="Ruim",IFERROR(INDEX('EQUIPAMENTOS_EFICIENTES (BDD)'!U:U,MATCH(1,('EQUIPAMENTOS_EFICIENTES (BDD)'!O:O=D5)*('EQUIPAMENTOS_EFICIENTES (BDD)'!T:T=E5),0)),0),0)} -> 0 | AA5: =M5 -> 8640 | AB5: =N5 -> 12 | AC5: =O5 -> 30 | AD5: =P5 -> 3 | AE5: =Q5 -> 1.4117647 | AF5: =(AA5*X5)/1000 -> 0.677376 | AG5: =AE5*X5/1000 -> 0.00011068235 | AH5: =S5-AG5 -> 0.11057167 | AI5: =(R5-AF5) -> 0 | AJ5: =IF(AI5>0,Y5*Z5,0) -> 0 | AK5: =AI5/478.332 -> 0
A6: =IF(UC_DADOS!$B$2=0,"",UC_DADOS!$B$2) -> 7041435180 | B6: Térreo | C6: Sala de freezer | D6: Freezer Horizontal | E6: Grande | F6: Bom | G6: Freezers | H6: 250 | I6: 0.6 | J6: =(H6*I6)/1000 -> 0.15 | K6: 1 | L6: 24 | M6: =L6*N6*O6 -> 8640 | N6: 12 | O6: 30 | P6: 3 | Q6: =N6*O6*P6/765 -> 1.4117647 | R6: =(J6*M6)/1000 -> 1.296 | S6: =J6*Q6 -> 0.21176471 | T6: {=IF(F6="Ruim",IFERROR(INDEX('EQUIPAMENTOS_EFICIENTES (BDD)'!O:O,MATCH(1,('EQUIPAMENTOS_EFICIENTES (BDD)'!O:O=D6)*('EQUIPAMENTOS_EFICIENTES (BDD)'!T:T=E6),0)),""),D6)} -> Freezer Horizontal | U6: =E6 -> Grande | V6: {=IF(F6="Ruim",IFERROR(INDEX('EQUIPAMENTOS_EFICIENTES (BDD)'!Q:Q,MATCH(1,('EQUIPAMENTOS_EFICIENTES (BDD)'!O:O=D6)*('EQUIPAMENTOS_EFICIENTES (BDD)'!T:T=E6),0)),H6),H6)} -> 250 | W6: {=IF(F6="Ruim",IFERROR(INDEX('EQUIPAMENTOS_EFICIENTES (BDD)'!S:S,MATCH(1,('EQUIPAMENTOS_EFICIENTES (BDD)'!O:O=D6)*('EQUIPAMENTOS_EFICIENTES (BDD)'!T:T=E6),0)),I6),I6)} -> 0.6 | X6: =(W6*V6)/1000 -> 0.15 | Y6: =K6 -> 1 | Z6: {=IF(F6="Ruim",IFERROR(INDEX('EQUIPAMENTOS_EFICIENTES (BDD)'!U:U,MATCH(1,('EQUIPAMENTOS_EFICIENTES (BDD)'!O:O=D6)*('EQUIPAMENTOS_EFICIENTES (BDD)'!T:T=E6),0)),0),0)} -> 0 | AA6: =M6 -> 8640 | AB6: =N6 -> 12 | AC6: =O6 -> 30 | AD6: =P6 -> 3 | AE6: =Q6 -> 1.4117647 | AF6: =(AA6*X6)/1000 -> 1.296 | AG6: =AE6*X6/1000 -> 0.00021176471 | AH6: =S6-AG6 -> 0.21155294 | AI6: =(R6-AF6) -> 0 | AJ6: =IF(AI6>0,Y6*Z6,0) -> 0 | AK6: =AI6/478.332 -> 0
A7: =IF(UC_DADOS!$B$2=0,"",UC_DADOS!$B$2) -> 7041435180 | B7: Anexo | C7: Refeitório | D7: Geladeira | E7: Pequeno | F7: Bom | G7: Refrigeradores | H7: 100 | I7: 0.45 | J7: =(H7*I7)/1000 -> 0.045 | K7: 1 | L7: 24 | M7: =L7*N7*O7 -> 8640 | N7: 12 | O7: 30 | P7: 3 | Q7: =N7*O7*P7/765 -> 1.4117647 | R7: =(J7*M7)/1000 -> 0.3888 | S7: =J7*Q7 -> 0.063529412 | T7: {=IF(F7="Ruim",IFERROR(INDEX('EQUIPAMENTOS_EFICIENTES (BDD)'!O:O,MATCH(1,('EQUIPAMENTOS_EFICIENTES (BDD)'!O:O=D7)*('EQUIPAMENTOS_EFICIENTES (BDD)'!T:T=E7),0)),""),D7)} -> Geladeira | U7: =E7 -> Pequeno | V7: {=IF(F7="Ruim",IFERROR(INDEX('EQUIPAMENTOS_EFICIENTES (BDD)'!Q:Q,MATCH(1,('EQUIPAMENTOS_EFICIENTES (BDD)'!O:O=D7)*('EQUIPAMENTOS_EFICIENTES (BDD)'!T:T=E7),0)),H7),H7)} -> 100 | W7: {=IF(F7="Ruim",IFERROR(INDEX('EQUIPAMENTOS_EFICIENTES (BDD)'!S:S,MATCH(1,('EQUIPAMENTOS_EFICIENTES (BDD)'!O:O=D7)*('EQUIPAMENTOS_EFICIENTES (BDD)'!T:T=E7),0)),I7),I7)} -> 0.45 | X7: =(W7*V7)/1000 -> 0.045 | Y7: =K7 -> 1 | Z7: {=IF(F7="Ruim",IFERROR(INDEX('EQUIPAMENTOS_EFICIENTES (BDD)'!U:U,MATCH(1,('EQUIPAMENTOS_EFICIENTES (BDD)'!O:O=D7)*('EQUIPAMENTOS_EFICIENTES (BDD)'!T:T=E7),0)),0),0)} -> 0 | AA7: =M7 -> 8640 | AB7: =N7 -> 12 | AC7: =O7 -> 30 | AD7: =P7 -> 3 | AE7: =Q7 -> 1.4117647 | AF7: =(AA7*X7)/1000 -> 0.3888 | AG7: =AE7*X7/1000 -> 6.3529412e-05 | AH7: =S7-AG7 -> 0.063465882 | AI7: =(R7-AF7) -> 0 | AJ7: =IF(AI7>0,Y7*Z7,0) -> 0 | AK7: =AI7/478.332 -> 0
A8: =IF(UC_DADOS!$B$2=0,"",UC_DADOS!$B$2) -> 7041435180 | B8: Anexo | C8: Refeitório | D8: Geladeira | E8: Grande | F8: Bom | G8: Refrigeradores | H8: 120 | I8: 0.45 | J8: =(H8*I8)/1000 -> 0.054 | K8: 1 | L8: 24 | M8: =L8*N8*O8 -> 8640 | N8: 12 | O8: 30 | P8: 3 | Q8: =N8*O8*P8/765 -> 1.4117647 | R8: =(J8*M8)/1000 -> 0.46656 | S8: =J8*Q8 -> 0.076235294 | T8: {=IF(F8="Ruim",IFERROR(INDEX('EQUIPAMENTOS_EFICIENTES (BDD)'!O:O,MATCH(1,('EQUIPAMENTOS_EFICIENTES (BDD)'!O:O=D8)*('EQUIPAMENTOS_EFICIENTES (BDD)'!T:T=E8),0)),""),D8)} -> Geladeira | U8: =E8 -> Grande | V8: {=IF(F8="Ruim",IFERROR(INDEX('EQUIPAMENTOS_EFICIENTES (BDD)'!Q:Q,MATCH(1,('EQUIPAMENTOS_EFICIENTES (BDD)'!O:O=D8)*('EQUIPAMENTOS_EFICIENTES (BDD)'!T:T=E8),0)),H8),H8)} -> 120 | W8: {=IF(F8="Ruim",IFERROR(INDEX('EQUIPAMENTOS_EFICIENTES (BDD)'!S:S,MATCH(1,('EQUIPAMENTOS_EFICIENTES (BDD)'!O:O=D8)*('EQUIPAMENTOS_EFICIENTES (BDD)'!T:T=E8),0)),I8),I8)} -> 0.45 | X8: =(W8*V8)/1000 -> 0.054 | Y8: =K8 -> 1 | Z8: {=IF(F8="Ruim",IFERROR(INDEX('EQUIPAMENTOS_EFICIENTES (BDD)'!U:U,MATCH(1,('EQUIPAMENTOS_EFICIENTES (BDD)'!O:O=D8)*('EQUIPAMENTOS_EFICIENTES (BDD)'!T:T=E8),0)),0),0)} -> 0 | AA8: =M8 -> 8640 | AB8: =N8 -> 12 | AC8: =O8 -> 30 | AD8: =P8 -> 3 | AE8: =Q8 -> 1.4117647 | AF8: =(AA8*X8)/1000 -> 0.46656 | AG8: =AE8*X8/1000 -> 7.6235294e-05 | AH8: =S8-AG8 -> 0.076159059 | AI8: =(R8-AF8) -> 0 | AJ8: =IF(AI8>0,Y8*Z8,0) -> 0 | AK8: =AI8/478.332 -> 0
A9: =IF(UC_DADOS!$B$2=0,"",UC_DADOS!$B$2) -> 7041435180 | B9: Térreo | C9: Circulação | D9: Bebedouro | E9: Médio | F9: Bom | G9: Refrigeradores | H9: 220 | I9: 0.6 | J9: =(H9*I9)/1000 -> 0.132 | K9: 1 | L9: 24 | M9: =L9*N9*O9 -> 8640 | N9: 12 | O9: 30 | P9: 3 | Q9: =N9*O9*P9/765 -> 1.4117647 | R9: =(J9*M9)/1000 -> 1.14048 | S9: =J9*Q9 -> 0.18635294 | T9: {=IF(F9="Ruim",IFERROR(INDEX('EQUIPAMENTOS_EFICIENTES (BDD)'!O:O,MATCH(1,('EQUIPAMENTOS_EFICIENTES (BDD)'!O:O=D9)*('EQUIPAMENTOS_EFICIENTES (BDD)'!T:T=E9),0)),""),D9)} -> Bebedouro | U9: =E9 -> Médio | V9: {=IF(F9="Ruim",IFERROR(INDEX('EQUIPAMENTOS_EFICIENTES (BDD)'!Q:Q,MATCH(1,('EQUIPAMENTOS_EFICIENTES (BDD)'!O:O=D9)*('EQUIPAMENTOS_EFICIENTES (BDD)'!T:T=E9),0)),H9),H9)} -> 220 | W9: {=IF(F9="Ruim",IFERROR(INDEX('EQUIPAMENTOS_EFICIENTES (BDD)'!S:S,MATCH(1,('EQUIPAMENTOS_EFICIENTES (BDD)'!O:O=D9)*('EQUIPAMENTOS_EFICIENTES (BDD)'!T:T=E9),0)),I9),I9)} -> 0.6 | X9: =(W9*V9)/1000 -> 0.132 | Y9: =K9 -> 1 | Z9: {=IF(F9="Ruim",IFERROR(INDEX('EQUIPAMENTOS_EFICIENTES (BDD)'!U:U,MATCH(1,('EQUIPAMENTOS_EFICIENTES (BDD)'!O:O=D9)*('EQUIPAMENTOS_EFICIENTES (BDD)'!T:T=E9),0)),0),0)} -> 0 | AA9: =M9 -> 8640 | AB9: =N9 -> 12 | AC9: =O9 -> 30 | AD9: =P9 -> 3 | AE9: =Q9 -> 1.4117647 | AF9: =(AA9*X9)/1000 -> 1.14048 | AG9: =AE9*X9/1000 -> 0.00018635294 | AH9: =S9-AG9 -> 0.18616659 | AI9: =(R9-AF9) -> 0 | AJ9: =IF(AI9>0,Y9*Z9,0) -> 0 | AK9: =AI9/478.332 -> 0
D10: TOTAL | J10: =SUBTOTAL(9,J3:J9) -> 0.6169 | K10: =SUBTOTAL(9,K3:K9) -> 7 | R10: =SUBTOTAL(9,R3:R9) -> 5.330016 | S10: =SUBTOTAL(9,S3:S9) -> 0.87091765 | X10: =SUBTOTAL(9,X3:X9) -> 0.6079 | Y10: =SUM(Y3:Y9) -> 7 | Z10: =SUBTOTAL(9,Z3:Z6) -> 0 | AF10: =SUBTOTAL(9,AF3:AF9) -> 5.252256 | AG10: =SUBTOTAL(9,AG3:AG6) -> 0.00053209412 | AH10: =SUM(AH3:AH9) -> 0.87005944 | AI10: =SUM(AI3:AI9) -> 0.07776 | AJ10: =SUM(AJ3:AJ6) -> 0 | AK10: =SUM(AK3:AK6) -> 0.00016256491

Sheet Sistemas de Iluminação
A1: Unidade Consumidora | E1: SITUAÇÃO ATUAL | S1: SISTEMA PROPOSTO | AG1: RESULTADOS ESPERADOS | AI1: RESULTADO AUTOMAÇÃO (15%)
